Workbook
Name ___xlnm.Print_Area: 'Cash Flow'!$A$1:$BA$39
Name __xlnm.Print_Area: 'Cash Flow'!$A$1:$BA$39
Name ___xlnm.Print_Area: '4B. Tel. Expense Assumptions'!$B$1:$R$68
Name ___xlnm.Print_Titles: '4B. Tel. Expense Assumptions'!$D:$D
Name __xlnm.Print_Area: '4B. Tel. Expense Assumptions'!$B$1:$R$68
Name __xlnm.Print_Titles: '4B. Tel. Expense Assumptions'!$D:$D
Name ___xlnm.Print_Area: '6B. Pre-Launch Exps. - Detail'!$A$1:$Q$132
Name ___xlnm.Print_Titles: '6B. Pre-Launch Exps. - Detail'!$C:$C
Name __xlnm.Print_Area: '6B. Pre-Launch Exps. - Detail'!$A$1:$Q$132
Name __xlnm.Print_Titles: '6B. Pre-Launch Exps. - Detail'!$C:$C
Name ___xlnm.Print_Area: 'Headcount & Salaries - 2'!$A$1:$BG$84
Name __xlnm.Print_Area: 'Headcount & Salaries - 2'!$A$1:$BG$84
Name ___xlnm.Print_Area: 'Income Statement'!$A$1:$BB$41
Name __xlnm.Print_Area: 'Income Statement'!$A$1:$BB$41
Name ___xlnm.Print_Area: 'Balance Sheet'!$A$1:$BB$45
Name __xlnm.Print_Area: 'Balance Sheet'!$A$1:$BB$45
Name ___xlnm.Print_Area: 'Depreciation & Amortization '!$A$1:$AA$74
Name __xlnm.Print_Area: 'Depreciation & Amortization '!$A$1:$AA$74
Name ___xlnm.Print_Area: Valuation!$A$1:$BB$7
Name __xlnm.Print_Area: Valuation!$A$1:$BB$7
Name ___xlnm.Print_Area: Summary!$A$1:$I$43
Name __xlnm.Print_Area: Summary!$A$1:$I$43

Sheet 1A. Consolidated - FY P&L
B2: PURE TECHNOLOGY INC.
B4: TELEPHONE - HARDWARE & MARKET RESEARCH SERVICES
B6: PROJECTED INCOME STATEMENT
B8: PRE-LAUNCH (MONTHS -12 to -1) AND POST-LAUNCH (YEARS 1 - 5)
B10: AT August 25th, 2025
G11: Consolidated Financials - PT (Core Model), PI, CPG, Camera Commerce, etc
I15: Pre-Launch | J15: Post-Launch
I18: Year 0 | J18: Year 1 | K18: Year 2 | L18: Year 3 | M18: Year 4 | N18: Year 5
I19: Months -12 to -1 | J19: Months 1 - 12 | K19: Months 13 - 24 | L19: Months 25 - 36 | M19: Months 37 - 48 | N19: Months 49 - 60
B23: MOBILE TELEPHONES DEPLOYED
B26: ● | C26: Full-Year Average | I26: - - | J26: ='3C. Tel. - Revenue Drivers - 1 '!V79 | K26: ='3C. Tel. - Revenue Drivers - 1 '!V97 | L26: ='3C. Tel. - Revenue Drivers - 1 '!V115 | M26: ='3C. Tel. - Revenue Drivers - 1 '!V133 | N26: ='3C. Tel. - Revenue Drivers - 1 '!V151
B27: ● | C27: End of Year | I27: - - | J27: ='3C. Tel. - Revenue Drivers - 1 '!V75 | K27: ='3C. Tel. - Revenue Drivers - 1 '!V93 | L27: ='3C. Tel. - Revenue Drivers - 1 '!V111 | M27: ='3C. Tel. - Revenue Drivers - 1 '!V129 | N27: ='3C. Tel. - Revenue Drivers - 1 '!V147
B29: REVENUE
B31: ● | C31: Hardware Subsidies* | I31: ='2A. Cash Forecast'!V25+'2A. Cash Forecast'!S29 | J31: ='3B. Tel. - Rev. Detail x Month'!W55 | K31: ='3B. Tel. - Rev. Detail x Month'!W93 | L31: ='3B. Tel. - Rev. Detail x Month'!W131 | M31: ='3B. Tel. - Rev. Detail x Month'!W169 | N31: ='3B. Tel. - Rev. Detail x Month'!W207
B32: ● | C32: Total Revenue, Market Research Services / Core Model | I32: 0 | J32: ='3B. Tel. - Rev. Detail x Month'!W296 | K32: ='3B. Tel. - Rev. Detail x Month'!W328 | L32: ='3B. Tel. - Rev. Detail x Month'!W360 | M32: ='3B. Tel. - Rev. Detail x Month'!W392 | N32: ='3B. Tel. - Rev. Detail x Month'!W424
B33: ● | C33: Total Revenue, Pure Influence | I33: ='2A. Cash Forecast'!V27 | J33: ='2A. Cash Forecast'!AK27 | K33: ='2A. Cash Forecast'!AZ27 | L33: ='2A. Cash Forecast'!BO27 | M33: ='2A. Cash Forecast'!CD27 | N33: ='2A. Cash Forecast'!CS27
B34: ● | C34: Total Revenue, CPG Model | I34: ='2A. Cash Forecast'!V30 | J34: ='2A. Cash Forecast'!AK30 | K34: ='2A. Cash Forecast'!AZ30 | L34: ='2A. Cash Forecast'!BO30 | M34: ='2A. Cash Forecast'!CD30 | N34: ='2A. Cash Forecast'!CS30
B35: ● | C35: Total Revenue, Camera Commerce | I35: ='2A. Cash Forecast'!V31 | J35: ='2A. Cash Forecast'!AK31 | K35: ='2A. Cash Forecast'!AZ31 | L35: ='2A. Cash Forecast'!BO31 | M35: ='2A. Cash Forecast'!CD31 | N35: ='2A. Cash Forecast'!CS31
B36: ● | C36: Total Revenue, Pure Research | I36: ='2A. Cash Forecast'!V28 | J36: ='8. Pure Research - 1 of 2'!N36 | K36: ='8. Pure Research - 1 of 2'!S36 | L36: ='8. Pure Research - 1 of 2'!X36 | M36: ='8. Pure Research - 1 of 2'!AC36 | N36: ='8. Pure Research - 1 of 2'!AH36
B37: ● | C37: Total Revenue, PureBrain | I37: =+'11. PureBrain'!I22 | J37: =+'11. PureBrain'!J22 | K37: =+'11. PureBrain'!K22 | L37: =+'11. PureBrain'!L22 | M37: =+'11. PureBrain'!M22 | N37: =+'11. PureBrain'!N22
D40: TOTAL REVENUE | I40: =SUM(I31:I37) | J40: =SUM(J31:J37) | K40: =SUM(K31:K37) | L40: =SUM(L31:L37) | M40: =SUM(M31:M37) | N40: =SUM(N31:N37)
B42: COST OF GOODS SOLD
B43: ● | C43: Hardware COGS | I43: ='6A. Pre-Launch Exps. - Roll-Up'!X41+'2A. Cash Forecast'!T49 | J43: ='3B. Tel. - Rev. Detail x Month'!W62+'3B. Tel. - Rev. Detail x Month'!W75 | K43: ='3B. Tel. - Rev. Detail x Month'!W100+'3B. Tel. - Rev. Detail x Month'!W109+'3B. Tel. - Rev. Detail x Month'!W113 | L43: ='3B. Tel. - Rev. Detail x Month'!W138+'3B. Tel. - Rev. Detail x Month'!W147+'3B. Tel. - Rev. Detail x Month'!W151 | M43: ='3B. Tel. - Rev. Detail x Month'!W176+'3B. Tel. - Rev. Detail x Month'!W185+'3B. Tel. - Rev. Detail x Month'!W189 | N43: ='3B. Tel. - Rev. Detail x Month'!W214+'3B. Tel. - Rev. Detail x Month'!W223+'3B. Tel. - Rev. Detail x Month'!W227
B44: ● | C44: PureBrain COGS | I44: =+'11. PureBrain'!I27 | J44: =+'11. PureBrain'!J27 | K44: =+'11. PureBrain'!K27 | L44: =+'11. PureBrain'!L27 | M44: =+'11. PureBrain'!M27 | N44: =+'11. PureBrain'!N27
C45: COGS | I45: =I43+I44 | J45: =J43+J44 | K45: =K43+K44 | L45: =L43+L44 | M45: =M43+M44 | N45: =N43+N44
B47: NET OPERATING MARGIN | I47: =I39-I43 | J47: =J39-J43 | K47: =K39-K43 | L47: =L39-L43 | M47: =M39-M43 | N47: =N39-N43
B49: OPERATING EXPENSES | P49: % of Total Revenue
B52: ● | C52: People Cost (Salaries, ER Taxes, Benefits) | I52: ='6A. Pre-Launch Exps. - Roll-Up'!X35 | J52: ='4A. Tel. - Exps. & OI x Month'!AA41 | K52: ='4A. Tel. - Exps. & OI x Month'!Y133 | L52: ='4A. Tel. - Exps. & OI x Month'!Y225 | M52: ='4A. Tel. - Exps. & OI x Month'!Y317 | N52: ='4A. Tel. - Exps. & OI x Month'!Y409 | P52: =J52/J40 | Q52: =K52/K40 | R52: =L52/L40 | S52: =M52/M40 | T52: =N52/N40
B53: ● | C53: Research and Development | I53: ='6A. Pre-Launch Exps. - Roll-Up'!X39 | J53: ='4A. Tel. - Exps. & OI x Month'!Y45 | K53: ='4A. Tel. - Exps. & OI x Month'!Y137 | L53: ='4A. Tel. - Exps. & OI x Month'!Y229 | M53: ='4A. Tel. - Exps. & OI x Month'!Y321 | N53: ='4A. Tel. - Exps. & OI x Month'!Y413 | P53: =J53/J$40 | Q53: =K53/K$40 | R53: =L53/L$40 | S53: =M53/M$40 | T53: =N53/N$40
B54: ● | C54: Sales and Marketing | I54: ='6A. Pre-Launch Exps. - Roll-Up'!X53 | J54: ='4A. Tel. - Exps. & OI x Month'!Y54 | K54: ='4A. Tel. - Exps. & OI x Month'!Y146 | L54: ='4A. Tel. - Exps. & OI x Month'!Y238 | M54: ='4A. Tel. - Exps. & OI x Month'!Y330 | N54: ='4A. Tel. - Exps. & OI x Month'!Y422 | P54: =J54/J$40 | Q54: =K54/K$40 | R54: =L54/L$40 | S54: =M54/M$40 | T54: =N54/N$40
B55: ● | C55: Occupancy | I55: ='6A. Pre-Launch Exps. - Roll-Up'!X62 | J55: ='4A. Tel. - Exps. & OI x Month'!Y63 | K55: ='4A. Tel. - Exps. & OI x Month'!Y155 | L55: ='4A. Tel. - Exps. & OI x Month'!Y247 | M55: ='4A. Tel. - Exps. & OI x Month'!Y339 | N55: ='4A. Tel. - Exps. & OI x Month'!Y431 | P55: =J55/J$40 | Q55: =K55/K$40 | R55: =L55/L$40 | S55: =M55/M$40 | T55: =N55/N$40
B56: ● | C56: General and Administrative | I56: ='6A. Pre-Launch Exps. - Roll-Up'!X87 | J56: ='4A. Tel. - Exps. & OI x Month'!Y84 | K56: ='4A. Tel. - Exps. & OI x Month'!Y176 | L56: ='4A. Tel. - Exps. & OI x Month'!Y268 | M56: ='4A. Tel. - Exps. & OI x Month'!Y360 | N56: ='4A. Tel. - Exps. & OI x Month'!Y452 | P56: =J56/J$40 | Q56: =K56/K$40 | R56: =L56/L$40 | S56: =M56/M$40 | T56: =N56/N$40
B57: ● | C57: Customer Rewards | I57: ='2A. Cash Forecast'!V53 | J57: ='2A. Cash Forecast'!AK53 | K57: ='2A. Cash Forecast'!AZ53 | L57: ='2A. Cash Forecast'!BO53 | M57: ='2A. Cash Forecast'!CD53 | N57: ='2A. Cash Forecast'!CS53 | P57: =J57/J$40 | Q57: =K57/K$40 | R57: =L57/L$40 | S57: =M57/M$40 | T57: =N57/N$40
B58: ● | C58: Pure Influence Expenses | I58: ='2A. Cash Forecast'!V56 | J58: ='2A. Cash Forecast'!AK56 | K58: ='2A. Cash Forecast'!AZ56 | L58: ='2A. Cash Forecast'!BO56 | M58: ='2A. Cash Forecast'!CD56 | N58: ='2A. Cash Forecast'!CS56 | P58: =J58/J$40 | Q58: =K58/K$40 | R58: =L58/L$40 | S58: =M58/M$40 | T58: =N58/N$40
B59: ● | C59: CPG Model - Expenses | I59: ='2A. Cash Forecast'!V57 | J59: ='2A. Cash Forecast'!AK57 | K59: ='2A. Cash Forecast'!AZ57 | L59: ='2A. Cash Forecast'!BO57 | M59: ='2A. Cash Forecast'!CD57 | N59: ='2A. Cash Forecast'!CS57 | P59: =J59/J$40 | Q59: =K59/K$40 | R59: =L59/L$40 | S59: =M59/M$40 | T59: =N59/N$40
B60: ● | C60: Camera Commerce - Expenses | I60: ='2A. Cash Forecast'!V58 | J60: ='2A. Cash Forecast'!AK58 | K60: ='2A. Cash Forecast'!AZ58 | L60: ='2A. Cash Forecast'!BO58 | M60: ='2A. Cash Forecast'!CD58 | N60: ='2A. Cash Forecast'!CS58 | P60: =J60/J$40 | Q60: =K60/K$40 | R60: =L60/L$40 | S60: =M60/M$40 | T60: =N60/N$40
B61: ● | C61: Capital Expenditures | I61: ='2A. Cash Forecast'!V55 | J61: ='2A. Cash Forecast'!AK55 | K61: ='2A. Cash Forecast'!AZ55 | L61: ='2A. Cash Forecast'!BO55 | M61: ='2A. Cash Forecast'!CD55 | N61: ='2A. Cash Forecast'!CS55 | P61: =J61/J$40 | Q61: =K61/K$40 | R61: =L61/L$40 | S61: =M61/M$40 | T61: =N61/N$40
B62: ● | C62: One Time Legacy Expenses + Strategic Investments | I62: ='2A. Cash Forecast'!V44+'2A. Cash Forecast'!V45+'2A. Cash Forecast'!V54+'2A. Cash Forecast'!V46 | J62: ='2A. Cash Forecast'!AK46 | K62: ='2A. Cash Forecast'!AZ46+'2A. Cash Forecast'!AZ59 | L62: ='2A. Cash Forecast'!BO46 | M62: ='2A. Cash Forecast'!CD46 | N62: ='2A. Cash Forecast'!CS46 | P62: =J62/J$40 | Q62: =K62/K$40 | R62: =L62/L$40 | S62: =M62/M$40 | T62: =N62/N$40
B63: ● | C63: PureBrain Operating Expenses | I63: =+'11. PureBrain'!I38 | J63: =+'11. PureBrain'!J38 | K63: =+'11. PureBrain'!K38 | L63: =+'11. PureBrain'!L38 | M63: =+'11. PureBrain'!M38 | N63: =+'11. PureBrain'!N38 | P63: =J63/J$40 | Q63: =K63/K$40 | R63: =L63/L$40 | S63: =M63/M$40 | T63: =N63/N$40
D66: TOTAL OPERATING EXPENSES | I66: =SUM(I50:I60)+I63 | J66: =SUM(J50:J60)+J63 | K66: =SUM(K50:K60)+K63 | L66: =SUM(L50:L60)+L63 | M66: =SUM(M50:M60)+M63 | N66: =SUM(N50:N60)+N63 | P66: =J63/J$39 | Q66: =K63/K$39 | R66: =L63/L$39 | S66: =M63/M$39 | T66: =N63/N$39
...

Sheet 2A. Cash Forecast
B2: PURE TECHNOLOGY INC.
B4: CASH FORECAST
B6: BY MONTH, MONTHS -12 THROUGH -1 AND MONTHS 1 - 60
B8: AT August 25th, 2025
I13: Pre-Launch (Twelve Months) | X13: Post-Launch | AM13: Post-Launch | BB13: Post-Launch | BQ13: Post-Launch | CF13: Post-Launch
I16: Month | J16: Month | K16: Month | L16: Month | M16: Month | N16: Month | O16: Month | P16: Month | Q16: Month | R16: Month | S16: Month | T16: Month | V16: Total | X16: Month | Y16: Month | Z16: Month | AA16: Month | AB16: Month | AC16: Month | AD16: Month | AE16: Month | AF16: Month | AG16: Month | AH16: Month | AI16: Month | AK16: Total | AM16: Month | AN16: Month | AO16: Month | AP16: Month | AQ16: Month | AR16: Month | AS16: Month | AT16: Month | AU16: Month | AV16: Month | AW16: Month | AX16: Month | AZ16: Total | BB16: Month | BC16: Month | BD16: Month | BE16: Month | BF16: Month | BG16: Month | BH16: Month | BI16: Month | BJ16: Month | BK16: Month | BL16: Month | BM16: Month | BO16: Total | BQ16: Month | BR16: Month | BS16: Month | BT16: Month | BU16: Month | BV16: Month | BW16: Month | BX16: Month | BY16: Month | BZ16: Month | CA16: Month | CB16: Month | CD16: Total | CF16: Month | CG16: Month | CH16: Month | CI16: Month | CJ16: Month | CK16: Month | CL16: Month | CM16: Month | CN16: Month | CO16: Month | CP16: Month | CQ16: Month | CS16: Total
I17: -12 | J17: -11 | K17: -10 | L17: -9 | M17: =((L17)+(1)) | N17: =((M17)+(1)) | O17: =((N17)+(1)) | P17: =((O17)+(1)) | Q17: =((P17)+(1)) | R17: =((Q17)+(1)) | S17: =((R17)+(1)) | T17: =((S17)+(1)) | V17: Months -12 to -1 | X17: 1 | Y17: =((X17)+(1)) | Z17: =((Y17)+(1)) | AA17: =((Z17)+(1)) | AB17: =((AA17)+(1)) | AC17: =((AB17)+(1)) | AD17: =((AC17)+(1)) | AE17: =((AD17)+(1)) | AF17: =((AE17)+(1)) | ... AI17: =((AH17)+(1)) | AK17: Months 1 - 12 | AM17: 13 | AN17: =((AM17)+(1)) | AO17: =((AN17)+(1)) | AP17: =((AO17)+(1)) | AQ17: =((AP17)+(1)) | AR17: =((AQ17)+(1)) | AS17: =((AR17)+(1)) | AT17: =((AS17)+(1)) | AU17: =((AT17)+(1)) | ... AX17: =((AW17)+(1)) | AZ17: Months 13 - 24 | BB17: 25 | BC17: =((BB17)+(1)) | BD17: =((BC17)+(1)) | BE17: =((BD17)+(1)) | BF17: =((BE17)+(1)) | BG17: =((BF17)+(1)) | BH17: =((BG17)+(1)) | BI17: =((BH17)+(1)) | BJ17: =((BI17)+(1)) | ... BM17: =((BL17)+(1)) | BO17: Months 25 - 36 | BQ17: 37 | BR17: =((BQ17)+(1)) | BS17: =((BR17)+(1)) | BT17: =((BS17)+(1)) | BU17: =((BT17)+(1)) | BV17: =((BU17)+(1)) | BW17: =((BV17)+(1)) | BX17: =((BW17)+(1)) | BY17: =((BX17)+(1)) | ... CB17: =((CA17)+(1)) | CD17: Months 37 - 48 | CF17: 49 | CG17: =((CF17)+(1)) | CH17: =((CG17)+(1)) | CI17: =((CH17)+(1)) | CJ17: =((CI17)+(1)) | CK17: =((CJ17)+(1)) | CL17: =((CK17)+(1)) | CM17: =((CL17)+(1)) | CN17: =((CM17)+(1)) | ... CQ17: =((CP17)+(1)) | CS17: Months 49 - 60
B21: Beginning Balance | I21: =20000000+1000 | J21: =(I73) | K21: =(J73) | L21: =(K73) | M21: =(L73) | N21: =(M73) | O21: =(N73) | P21: =(O73) | Q21: =(P73) | ... T21: =(S73) | V21: =(I21) | X21: =(T73) | Y21: =(X73) | Z21: =(Y73) | AA21: =(Z73) | AB21: =(AA73) | AC21: =(AB73) | AD21: =(AC73) | AE21: =(AD73) | AF21: =(AE73) | ... AI21: =(AH73) | AK21: =(X21) | AM21: =(AI73) | AN21: =(AM73) | AO21: =(AN73) | AP21: =(AO73) | AQ21: =(AP73) | AR21: =(AQ73) | AS21: =(AR73) | AT21: =(AS73) | AU21: =(AT73) | ... AX21: =(AW73) | AZ21: =(AM21) | BB21: =(AX73) | BC21: =(BB73) | BD21: =(BC73) | BE21: =(BD73) | BF21: =(BE73) | BG21: =(BF73) | BH21: =(BG73) | BI21: =(BH73) | BJ21: =(BI73) | ... BM21: =(BL73) | BO21: =(BB21) | BQ21: =(BM73) | BR21: =(BQ73) | BS21: =(BR73) | BT21: =(BS73) | BU21: =(BT73) | BV21: =(BU73) | BW21: =(BV73) | BX21: =(BW73) | BY21: =(BX73) | ... CB21: =(CA73) | CD21: =(BQ21) | CF21: =(CB73) | CG21: =(CF73) | CH21: =(CG73) | CI21: =(CH73) | CJ21: =(CI73) | CK21: =(CJ73) | CL21: =(CK73) | CM21: =(CL73) | CN21: =(CM73) | ... CQ21: =(CP73) | CS21: =(CF21)
B24: Cash Receipts
B25: ● | C25: Telephone Sales | I25: ='2B. Cash Collections'!I20 | J25: ='2B. Cash Collections'!J20 | K25: ='2B. Cash Collections'!K20 | L25: ='2B. Cash Collections'!L20 | M25: ='2B. Cash Collections'!M20 | N25: ='2B. Cash Collections'!N20 | O25: ='2B. Cash Collections'!O20 | P25: ='2B. Cash Collections'!P20 | ... T25: ='2B. Cash Collections'!T20 | V25: =SUM(I25:T25) | X25: ='2B. Cash Collections'!X20 | Y25: ='2B. Cash Collections'!Y20 | Z25: ='2B. Cash Collections'!Z20 | AA25: ='2B. Cash Collections'!AA20 | AB25: ='2B. Cash Collections'!AB20 | AC25: ='2B. Cash Collections'!AC20 | AD25: ='2B. Cash Collections'!AD20 | AE25: ='2B. Cash Collections'!AE20 | ... AI25: ='2B. Cash Collections'!AI20 | AK25: =SUM(X25:AI25) | AM25: ='2B. Cash Collections'!AM20 | AN25: ='2B. Cash Collections'!AN20 | AO25: ='2B. Cash Collections'!AO20 | AP25: ='2B. Cash Collections'!AP20 | AQ25: ='2B. Cash Collections'!AQ20 | AR25: ='2B. Cash Collections'!AR20 | AS25: ='2B. Cash Collections'!AS20 | AT25: ='2B. Cash Collections'!AT20 | ... AX25: ='2B. Cash Collections'!AX20 | AZ25: =SUM(AM25:AX25) | BB25: ='2B. Cash Collections'!BB20 | BC25: ='2B. Cash Collections'!BC20 | BD25: ='2B. Cash Collections'!BD20 | BE25: ='2B. Cash Collections'!BE20 | BF25: ='2B. Cash Collections'!BF20 | BG25: ='2B. Cash Collections'!BG20 | BH25: ='2B. Cash Collections'!BH20 | BI25: ='2B. Cash Collections'!BI20 | ... BM25: ='2B. Cash Collections'!BM20 | BO25: =SUM(BB25:BM25) | BQ25: ='2B. Cash Collections'!BQ20 | BR25: ='2B. Cash Collections'!BR20 | BS25: ='2B. Cash Collections'!BS20 | BT25: ='2B. Cash Collections'!BT20 | BU25: ='2B. Cash Collections'!BU20 | BV25: ='2B. Cash Collections'!BV20 | BW25: ='2B. Cash Collections'!BW20 | BX25: ='2B. Cash Collections'!BX20 | ... CB25: ='2B. Cash Collections'!CB20 | CD25: =SUM(BQ25:CB25) | CF25: ='2B. Cash Collections'!CF20 | CG25: ='2B. Cash Collections'!CG20 | CH25: ='2B. Cash Collections'!CH20 | CI25: ='2B. Cash Collections'!CI20 | CJ25: ='2B. Cash Collections'!CJ20 | CK25: ='2B. Cash Collections'!CK20 | CL25: ='2B. Cash Collections'!CL20 | CM25: ='2B. Cash Collections'!CM20 | ... CQ25: ='2B. Cash Collections'!CQ20 | CS25: =SUM(CF25:CQ25)
B26: ● | C26: Market Research Services / Core Model | I26: 0 | J26: 0 | K26: 0 | L26: 0 | M26: 0 | N26: 0 | O26: 0 | P26: 0 | Q26: 0 | R26: 0 | S26: 0 | T26: 0 | V26: =SUM(I26:T26) | X26: ='2B. Cash Collections'!X31 | Y26: ='2B. Cash Collections'!Y31 | Z26: ='2B. Cash Collections'!Z31 | AA26: ='2B. Cash Collections'!AA31 | AB26: ='2B. Cash Collections'!AB31 | AC26: ='2B. Cash Collections'!AC31 | AD26: ='2B. Cash Collections'!AD31 | AE26: ='2B. Cash Collections'!AE31 | ... AI26: ='2B. Cash Collections'!AI31 | AK26: =SUM(X26:AI26) | AM26: ='2B. Cash Collections'!AM31 | AN26: ='2B. Cash Collections'!AN31 | AO26: ='2B. Cash Collections'!AO31 | AP26: ='2B. Cash Collections'!AP31 | AQ26: ='2B. Cash Collections'!AQ31 | AR26: ='2B. Cash Collections'!AR31 | AS26: ='2B. Cash Collections'!AS31 | AT26: ='2B. Cash Collections'!AT31 | ... AX26: ='2B. Cash Collections'!AX31 | AZ26: =SUM(AM26:AX26) | BB26: ='2B. Cash Collections'!BB31 | BC26: ='2B. Cash Collections'!BC31 | BD26: ='2B. Cash Collections'!BD31 | BE26: ='2B. Cash Collections'!BE31 | BF26: ='2B. Cash Collections'!BF31 | BG26: ='2B. Cash Collections'!BG31 | BH26: ='2B. Cash Collections'!BH31 | BI26: ='2B. Cash Collections'!BI31 | ... BM26: ='2B. Cash Collections'!BM31 | BO26: =SUM(BB26:BM26) | BQ26: ='2B. Cash Collections'!BQ31 | BR26: ='2B. Cash Collections'!BR31 | BS26: ='2B. Cash Collections'!BS31 | BT26: ='2B. Cash Collections'!BT31 | BU26: ='2B. Cash Collections'!BU31 | BV26: ='2B. Cash Collections'!BV31 | BW26: ='2B. Cash Collections'!BW31 | BX26: ='2B. Cash Collections'!BX31 | ... CB26: ='2B. Cash Collections'!CB31 | CD26: =SUM(BQ26:CB26) | CF26: ='2B. Cash Collections'!CF31 | CG26: ='2B. Cash Collections'!CG31 | CH26: ='2B. Cash Collections'!CH31 | CI26: ='2B. Cash Collections'!CI31 | CJ26: ='2B. Cash Collections'!CJ31 | CK26: ='2B. Cash Collections'!CK31 | CL26: ='2B. Cash Collections'!CL31 | CM26: ='2B. Cash Collections'!CM31 | ... CQ26: ='2B. Cash Collections'!CQ31 | CS26: =SUM(CF26:CQ26)
B27: ● | C27: Pure Influence | I27: 0 | J27: 0 | K27: 0 | L27: 0 | M27: 0 | N27: 0 | O27: 0 | P27: 0 | Q27: ='7. Pure Influence'!G16 | R27: ='7. Pure Influence'!H16 | S27: ='7. Pure Influence'!I16 | T27: ='7. Pure Influence'!J16 | V27: =SUM(I27:T27) | X27: ='7. Pure Influence'!K16 | Y27: ='7. Pure Influence'!L16 | Z27: ='7. Pure Influence'!M16 | AA27: ='7. Pure Influence'!N16 | AB27: =('7. Pure Influence'!O16) | AC27: =('7. Pure Influence'!P16) | AD27: =('7. Pure Influence'!Q16) | AE27: =('7. Pure Influence'!R16) | AF27: ='7. Pure Influence'!G33 | AG27: ='7. Pure Influence'!H33 | AH27: ='7. Pure Influence'!I33 | AI27: ='7. Pure Influence'!J33 | AK27: =SUM(X27:AI27) | AM27: ='7. Pure Influence'!K33 | AN27: ='7. Pure Influence'!L33 | AO27: ='7. Pure Influence'!M33 | AP27: ='7. Pure Influence'!N33 | AQ27: ='7. Pure Influence'!O33 | AR27: ='7. Pure Influence'!P33 | AS27: ='7. Pure Influence'!Q33 | AT27: ='7. Pure Influence'!R33 | AU27: ='7. Pure Influence'!G50 | AV27: ='7. Pure Influence'!H50 | AW27: ='7. Pure Influence'!I50 | AX27: ='7. Pure Influence'!J50 | AZ27: =SUM(AM27:AX27) | BB27: ='7. Pure Influence'!K50 | BC27: ='7. Pure Influence'!L50 | BD27: ='7. Pure Influence'!M50 | BE27: ='7. Pure Influence'!N50 | BF27: ='7. Pure Influence'!O50 | BG27: ='7. Pure Influence'!P50 | BH27: ='7. Pure Influence'!Q50 | BI27: ='7. Pure Influence'!R50 | BJ27: ='7. Pure Influence'!G67 | BK27: ='7. Pure Influence'!H67 | BL27: ='7. Pure Influence'!I67 | BM27: ='7. Pure Influence'!J67 | BO27: =SUM(BB27:BM27) | BQ27: ='7. Pure Influence'!K67 | BR27: ='7. Pure Influence'!L67 | BS27: ='7. Pure Influence'!M67 | BT27: ='7. Pure Influence'!N67 | BU27: ='7. Pure Influence'!O67 | BV27: ='7. Pure Influence'!P67 | BW27: ='7. Pure Influence'!Q67 | BX27: ='7. Pure Influence'!R67 | BY27: ='7. Pure Influence'!G84 | BZ27: ='7. Pure Influence'!H84 | CA27: ='7. Pure Influence'!I84 | CB27: ='7. Pure Influence'!J84 | CD27: =SUM(BQ27:CB27) | CF27: ='7. Pure Influence'!K84 | CG27: ='7. Pure Influence'!L84 | CH27: ='7. Pure Influence'!M84 | CI27: ='7. Pure Influence'!N84 | CJ27: ='7. Pure Influence'!O84 | CK27: ='7. Pure Influence'!P84 | CL27: ='7. Pure Influence'!Q84 | CM27: ='7. Pure Influence'!R84 | CN27: ='7. Pure Influence'!G101 | CO27: ='7. Pure Influence'!H101 | CP27: ='7. Pure Influence'!I101 | CQ27: ='7. Pure Influence'!J101 | CS27: =SUM(CF27:CQ27) | CU27: ='7. Pure Influence'!K101 | CV27: ='7. Pure Influence'!L101 | CW27: ='7. Pure Influence'!M101 | CX27: ='7. Pure Influence'!N101 | CY27: ='7. Pure Influence'!O101 | CZ27: ='7. Pure Influence'!P101 | DA27: ='7. Pure Influence'!Q101 | DB27: ='7. Pure Influence'!R101
B28: ● | C28: Pure Research - this is part of lead gen to distribute phones | I28: 0 | J28: 0 | K28: 0 | L28: 0 | M28: 0 | N28: 0 | O28: =('8. Pure Research - 1 of 2'!$I$40) | P28: =('8. Pure Research - 1 of 2'!$I$40) | Q28: =('8. Pure Research - 1 of 2'!$I$40) | R28: =('8. Pure Research - 1 of 2'!$I$40) | S28: =('8. Pure Research - 1 of 2'!$I$40) | T28: =('8. Pure Research - 1 of 2'!$I$40) | V28: =SUM(I28:T28) | X28: ='8. Pure Research - 1 of 2'!$N$40 | Y28: ='8. Pure Research - 1 of 2'!$N$40 | Z28: ='8. Pure Research - 1 of 2'!$N$40 | AA28: ='8. Pure Research - 1 of 2'!$N$40 | AB28: ='8. Pure Research - 1 of 2'!$N$40 | AC28: ='8. Pure Research - 1 of 2'!$N$40 | AD28: ='8. Pure Research - 1 of 2'!$N$40 | AE28: ='8. Pure Research - 1 of 2'!$N$40 | ... AI28: ='8. Pure Research - 1 of 2'!$N$40 | AK28: =SUM(X28:AI28) | AM28: ='8. Pure Research - 1 of 2'!$S$40 | AN28: ='8. Pure Research - 1 of 2'!$S$40 | AO28: ='8. Pure Research - 1 of 2'!$S$40 | AP28: ='8. Pure Research - 1 of 2'!$S$40 | AQ28: ='8. Pure Research - 1 of 2'!$S$40 | AR28: ='8. Pure Research - 1 of 2'!$S$40 | AS28: ='8. Pure Research - 1 of 2'!$S$40 | AT28: ='8. Pure Research - 1 of 2'!$S$40 | ... AX28: ='8. Pure Research - 1 of 2'!$S$40 | AZ28: =SUM(AM28:AX28) | BB28: ='8. Pure Research - 1 of 2'!$X$40 | BC28: ='8. Pure Research - 1 of 2'!$X$40 | BD28: ='8. Pure Research - 1 of 2'!$X$40 | BE28: ='8. Pure Research - 1 of 2'!$X$40 | BF28: ='8. Pure Research - 1 of 2'!$X$40 | BG28: ='8. Pure Research - 1 of 2'!$X$40 | BH28: ='8. Pure Research - 1 of 2'!$X$40 | BI28: ='8. Pure Research - 1 of 2'!$X$40 | ... BM28: ='8. Pure Research - 1 of 2'!$X$40 | BO28: =SUM(BB28:BM28) | BQ28: ='8. Pure Research - 1 of 2'!$AC$40 | BR28: ='8. Pure Research - 1 of 2'!$AC$40 | BS28: ='8. Pure Research - 1 of 2'!$AC$40 | BT28: ='8. Pure Research - 1 of 2'!$AC$40 | BU28: ='8. Pure Research - 1 of 2'!$AC$40 | BV28: ='8. Pure Research - 1 of 2'!$AC$40 | BW28: ='8. Pure Research - 1 of 2'!$AC$40 | BX28: ='8. Pure Research - 1 of 2'!$AC$40 | ... CB28: ='8. Pure Research - 1 of 2'!$AC$40 | CD28: =SUM(BQ28:CB28) | CF28: ='8. Pure Research - 1 of 2'!$AH$40 | CG28: ='8. Pure Research - 1 of 2'!$AH$40 | CH28: ='8. Pure Research - 1 of 2'!$AH$40 | CI28: ='8. Pure Research - 1 of 2'!$AH$40 | CJ28: ='8. Pure Research - 1 of 2'!$AH$40 | CK28: ='8. Pure Research - 1 of 2'!$AH$40 | CL28: ='8. Pure Research - 1 of 2'!$AH$40 | CM28: ='8. Pure Research - 1 of 2'!$AH$40 | ... CQ28: ='8. Pure Research - 1 of 2'!$AH$40 | CS28: =SUM(CF28:CQ28)
B29: ● | C29: Crowd Funding / Pre Sales / Program Opt Ins | I29: 0 | J29: 0 | K29: 0 | L29: 0 | M29: 0 | N29: 0 | O29: 0 | P29: 0 | Q29: 0 | R29: 0 | S29: ='2D. Crowd Funding'!G13 | T29: 0 | V29: =SUM(I29:T29) | X29: 0 | Y29: 0 | Z29: 0 | AA29: 0 | AB29: 0 | AC29: 0 | AD29: 0 | AE29: 0 | AF29: 0 | AG29: 0 | AH29: 0 | AI29: 0 | AK29: =SUM(X29:AI29) | AM29: 0 | AN29: 0 | AO29: 0 | AP29: 0 | AQ29: 0 | AR29: 0 | AS29: 0 | AT29: 0 | AU29: 0 | AV29: 0 | AW29: 0 | AX29: 0 | AZ29: =SUM(AM29:AX29) | BB29: 0 | BC29: 0 | BD29: 0 | BE29: 0 | BF29: 0 | BG29: 0 | BH29: 0 | BI29: 0 | BJ29: 0 | BK29: 0 | BL29: 0 | BM29: 0 | BO29: =SUM(BB29:BM29) | BQ29: 0 | BR29: 0 | BS29: 0 | BT29: 0 | BU29: 0 | BV29: 0 | BW29: 0 | BX29: 0 | BY29: 0 | BZ29: 0 | CA29: 0 | CB29: 0 | CD29: =SUM(BQ29:CB29) | CF29: 0 | CG29: 0 | CH29: 0 | CI29: 0 | CJ29: 0 | CK29: 0 | CL29: 0 | CM29: 0 | CN29: 0 | CO29: 0 | CP29: 0 | CQ29: 0 | CS29: =SUM(CF29:CQ29)
B30: ● | C30: CPG Model - Revenue | I30: 0 | J30: 0 | K30: 0 | L30: 0 | M30: 0 | N30: 0 | O30: 0 | P30: 0 | Q30: 0 | R30: 0 | S30: =Table13[[#Totals],[Month 1]] | T30: =Table13[[#Totals],[Month 2]] | V30: =SUM(I30:T30) | X30: =Table13[[#Totals],[Month 3]] | Y30: =Table13[[#Totals],[Month 4]] | Z30: =Table13[[#Totals],[Month 5]] | AA30: =Table13[[#Totals],[Month 6]] | AB30: =Table13[[#Totals],[Month 7]] | AC30: =Table13[[#Totals],[Month 8]] | AD30: =Table13[[#Totals],[Month 9]] | AE30: =Table13[[#Totals],[Month 10]] | AF30: =Table13[[#Totals],[Month 11]] | AG30: =Table13[[#Totals],[Month 12]] | AH30: =Table13[[#Totals],[Month 13]] | AI30: =Table13[[#Totals],[Month 14]] | AK30: =SUM(X30:AI30) | AM30: =Table13[[#Totals],[Month 15]] | AN30: =Table13[[#Totals],[Month 16]] | AO30: =Table13[[#Totals],[Month 17]] | AP30: =Table13[[#Totals],[Month 18]] | AQ30: =Table13[[#Totals],[Month 19]] | AR30: =Table13[[#Totals],[Month 20]] | AS30: =Table13[[#Totals],[Month 21]] | AT30: =Table13[[#Totals],[Month 22]] | AU30: =Table13[[#Totals],[Month 23]] | AV30: =Table13[[#Totals],[Month 24]] | AW30: =Table13[[#Totals],[Month 25]] | AX30: =Table13[[#Totals],[Month 26]] | AZ30: =SUM(AM30:AX30) | BB30: =Table13[[#Totals],[Month 27]] | BC30: =Table13[[#Totals],[Month 28]] | BD30: =Table13[[#Totals],[Month 29]] | BE30: =Table13[[#Totals],[Month 30]] | BF30: =Table13[[#Totals],[Month 31]] | BG30: =Table13[[#Totals],[Month 32]] | BH30: =Table13[[#Totals],[Month 33]] | BI30: =Table13[[#Totals],[Month 34]] | BJ30: =Table13[[#Totals],[Month 35]] | BK30: =Table13[[#Totals],[Month 36]] | BL30: =Table13[[#Totals],[Month 37]] | BM30: =Table13[[#Totals],[Month 38]] | BO30: =SUM(BB30:BM30) | BQ30: =Table13[[#Totals],[Month 39]] | BR30: =Table13[[#Totals],[Month 40]] | BS30: =Table13[[#Totals],[Month 41]] | BT30: =Table13[[#Totals],[Month 42]] | BU30: =Table13[[#Totals],[Month 43]] | BV30: =Table13[[#Totals],[Month 44]] | BW30: =Table13[[#Totals],[Month 45]] | BX30: =Table13[[#Totals],[Month 46]] | BY30: =Table13[[#Totals],[Month 47]] | BZ30: =Table13[[#Totals],[Month 48]] | CA30: =Table13[[#Totals],[Month 49]] | CB30: =Table13[[#Totals],[Month 50]] | CD30: =SUM(BQ30:CB30) | CF30: =Table13[[#Totals],[Month 51]] | CG30: =Table13[[#Totals],[Month 52]] | CH30: =Table13[[#Totals],[Month 53]] | CI30: =Table13[[#Totals],[Month 54]] | CJ30: =Table13[[#Totals],[Month 55]] | CK30: =Table13[[#Totals],[Month 56]] | CL30: =Table13[[#Totals],[Month 57]] | CM30: =Table13[[#Totals],[Month 58]] | CN30: =Table13[[#Totals],[Month 59]] | CO30: =Table13[[#Totals],[Month 60]] | CP30: 0 | CQ30: 0 | CS30: =SUM(CF30:CQ30)
B31: ● | C31: Camera Commerce | I31: 0 | J31: 0 | K31: 0 | L31: 0 | M31: 0 | N31: ='9. Camera Commerce'!B6 | O31: ='9. Camera Commerce'!C6 | P31: ='9. Camera Commerce'!D6 | Q31: ='9. Camera Commerce'!E6 | R31: ='9. Camera Commerce'!F6 | S31: ='9. Camera Commerce'!G6 | T31: ='9. Camera Commerce'!H6 | V31: =SUM(I31:T31) | X31: ='9. Camera Commerce'!I6 | Y31: ='9. Camera Commerce'!J6 | Z31: ='9. Camera Commerce'!K6 | AA31: ='9. Camera Commerce'!L6 | AB31: ='9. Camera Commerce'!M6 | AC31: ='9. Camera Commerce'!O6 | AD31: ='9. Camera Commerce'!P6 | AE31: ='9. Camera Commerce'!Q6 | AF31: ='9. Camera Commerce'!R6 | AG31: ='9. Camera Commerce'!S6 | AH31: ='9. Camera Commerce'!T6 | AI31: ='9. Camera Commerce'!U6 | AK31: =SUM(X31:AI31) | AM31: ='9. Camera Commerce'!V6 | AN31: ='9. Camera Commerce'!W6 | AO31: ='9. Camera Commerce'!X6 | AP31: ='9. Camera Commerce'!Y6 | AQ31: ='9. Camera Commerce'!Z6 | AR31: ='9. Camera Commerce'!AB6 | AS31: ='9. Camera Commerce'!AC6 | AT31: ='9. Camera Commerce'!AD6 | AU31: ='9. Camera Commerce'!AE6 | AV31: ='9. Camera Commerce'!AF6 | AW31: ='9. Camera Commerce'!AG6 | AX31: ='9. Camera Commerce'!AH6 | AZ31: =SUM(AM31:AX31) | BB31: ='9. Camera Commerce'!AI6 | BC31: ='9. Camera Commerce'!AJ6 | BD31: ='9. Camera Commerce'!AK6 | BE31: ='9. Camera Commerce'!AL6 | BF31: ='9. Camera Commerce'!AM6 | BG31: ='9. Camera Commerce'!AO6 | BH31: ='9. Camera Commerce'!AP6 | BI31: ='9. Camera Commerce'!AQ6 | BJ31: ='9. Camera Commerce'!AR6 | BK31: ='9. Camera Commerce'!AS6 | BL31: ='9. Camera Commerce'!AT6 | BM31: ='9. Camera Commerce'!AU6 | BO31: =SUM(BB31:BM31) | BQ31: ='9. Camera Commerce'!AV6 | BR31: ='9. Camera Commerce'!AW6 | BS31: ='9. Camera Commerce'!AX6 | BT31: ='9. Camera Commerce'!AY6 | BU31: ='9. Camera Commerce'!AZ6 | BV31: ='9. Camera Commerce'!BB6 | BW31: ='9. Camera Commerce'!BC6 | BX31: ='9. Camera Commerce'!BD6 | BY31: ='9. Camera Commerce'!BE6 | BZ31: ='9. Camera Commerce'!BF6 | CA31: ='9. Camera Commerce'!BG6 | CB31: ='9. Camera Commerce'!BH6 | CD31: =SUM(BQ31:CB31) | CF31: ='9. Camera Commerce'!BI6 | CG31: ='9. Camera Commerce'!BJ6 | CH31: ='9. Camera Commerce'!BK6 | CI31: ='9. Camera Commerce'!BL6 | CJ31: ='9. Camera Commerce'!BM6 | CS31: =SUM(CF31:CQ31)
B32: ● | C32: Capital Raise | I32: 0 | J32: 0 | K32: 0 | L32: 0 | M32: 0 | N32: 5000000 | O32: 0 | P32: 0 | Q32: 0 | R32: 0 | S32: 0 | T32: 0 | V32: =SUM(I32:T32) | X32: 0 | Y32: 43000000 | Z32: 0 | AA32: 0 | AB32: 0 | AC32: 0 | AD32: 0 | AE32: 0 | AF32: 0 | AG32: 0 | AH32: 0 | AI32: 0 | AK32: =SUM(X32:AI32) | AM32: 0 | AN32: 100000000 | AO32: 0 | AP32: 0 | AQ32: 0 | AR32: 0 | AS32: 0 | AT32: 0 | AU32: 0 | AV32: 0 | AW32: 0 | AX32: 0 | AZ32: =SUM(AM32:AX32) | BB32: 0 | BC32: 500000000 | BD32: 0 | BE32: 0 | BF32: 0 | BG32: 0 | BH32: 0 | BI32: 0 | BJ32: 0 | BK32: 0 | BL32: 0 | BM32: 0 | BO32: =SUM(BB32:BM32) | BQ32: 0 | BR32: 0 | BS32: 0 | BT32: 0 | BU32: 0 | BV32: 0 | BW32: 0 | BX32: 0 | BY32: 0 | BZ32: 0 | CA32: 0 | CB32: 0 | CD32: =SUM(BQ32:CB32) | CF32: 0 | CG32: 0 | CH32: 0 | CI32: 0 | CJ32: 0 | CK32: 0 | CL32: 0 | CM32: 0 | CN32: 0 | CO32: 0 | CP32: 0 | CQ32: 0 | CS32: =SUM(CF32:CQ32)
V33: =SUM(I33:T33) | AD33: 0 | AK33: =SUM(X33:AI33) | AM33: 0 | AN33: 0 | AO33: 0 | AP33: 0 | AQ33: 0 | AR33: 0 | AS33: 0 | AT33: 0 | AU33: 0 | AV33: 0 | AW33: 0 | AX33: 0 | AZ33: =SUM(AM33:AX33) | BB33: 0 | BC33: 0 | BD33: 0 | BE33: 0 | BF33: 0 | BG33: 0 | BH33: 0 | BI33: 0 | BJ33: 0 | BK33: 0 | BL33: 0 | BM33: 0 | BO33: =SUM(BB33:BM33) | BQ33: 0 | BR33: 0 | BS33: 0 | BT33: 0 | BU33: 0 | BV33: 0 | BW33: 0 | BX33: 0 | BY33: 0 | BZ33: 0 | CA33: 0 | CB33: 0 | CD33: =SUM(BQ33:CB33) | CF33: 0 | CG33: 0 | CH33: 0 | CI33: 0 | CJ33: 0 | CK33: 0 | CL33: 0 | CM33: 0 | CN33: 0 | CO33: 0 | CP33: 0 | CQ33: 0 | CS33: =SUM(CF33:CQ33)
B34: ● | C34: Working Capital Financing - Borrowings | I34: 0 | J34: 0 | K34: 0 | L34: 0 | M34: 0 | N34: 0 | O34: 0 | P34: 0 | Q34: 0 | R34: 0 | S34: 0 | T34: 0 | V34: =SUM(I34:T34) | X34: 0 | Y34: 0 | Z34: 0 | AA34: 0 | AB34: 0 | AC34: 0 | AD34: 0 | AE34: 0 | AF34: 0 | AG34: 0 | AH34: 0 | AI34: 0 | AK34: =SUM(X34:AI34) | AM34: 0 | AN34: 0 | AO34: 0 | AP34: 0 | AQ34: 0 | AR34: 0 | AS34: 0 | AT34: 0 | AU34: 0 | AV34: 0 | AW34: 0 | AX34: 0 | AZ34: =SUM(AM34:AX34) | BB34: 0 | BC34: 0 | BD34: 0 | BE34: 0 | BF34: 0 | BG34: 0 | BH34: 0 | BI34: 0 | BJ34: 0 | BK34: 0 | BL34: 0 | BM34: 0 | BO34: =SUM(BB34:BM34) | BQ34: 0 | BR34: 0 | BS34: 0 | BT34: 0 | BU34: 0 | BV34: 0 | BW34: 0 | BX34: 0 | BY34: 0 | BZ34: 0 | CA34: 0 | CB34: 0 | CD34: =SUM(BQ34:CB34) | CF34: 0 | CG34: 0 | CH34: 0 | CI34: 0 | CJ34: 0 | CK34: 0 | CL34: 0 | CM34: 0 | CN34: 0 | CO34: 0 | CP34: 0 | CQ34: 0 | CS34: =SUM(CF34:CQ34)
V35: =SUM(I35:T35) | AK35: =SUM(X35:AI35) | AZ35: =SUM(AM35:AX35) | BO35: =SUM(BB35:BM35) | CD35: =SUM(BQ35:CB35) | CS35: =SUM(CF35:CQ35)
V36: =SUM(I36:T36) | AK36: =SUM(X36:AI36) | AZ36: =SUM(AM36:AX36) | BO36: =SUM(BB36:BM36) | CD36: =SUM(BQ36:CB36) | CS36: =SUM(CF36:CQ36)
D37: Total Cash Disbursements | I37: =SUM(I25:I34) | J37: =SUM(J25:J34) | K37: =SUM(K25:K34) | L37: =SUM(L25:L34) | M37: =SUM(M25:M34) | N37: =SUM(N25:N34) | O37: =SUM(O25:O34) | P37: =SUM(P25:P34) | ... T37: =SUM(T25:T34) | V37: =SUM(V25:V34) | X37: =SUM(X25:X34) | Y37: =SUM(Y25:Y34) | Z37: =SUM(Z25:Z34) | AA37: =SUM(AA25:AA34) | AB37: =SUM(AB25:AB34) | AC37: =SUM(AC25:AC34) | AD37: =SUM(AD25:AD34) | AE37: =SUM(AE25:AE34) | ... AI37: =SUM(AI25:AI34) | AK37: =SUM(AK25:AK34) | AM37: =SUM(AM25:AM34) | AN37: =SUM(AN25:AN34) | AO37: =SUM(AO25:AO34) | AP37: =SUM(AP25:AP34) | AQ37: =SUM(AQ25:AQ34) | AR37: =SUM(AR25:AR34) | AS37: =SUM(AS25:AS34) | AT37: =SUM(AT25:AT34) | ... AX37: =SUM(AX25:AX34) | AZ37: =SUM(AZ25:AZ34) | BB37: =SUM(BB25:BB34) | BC37: =SUM(BC25:BC34) | BD37: =SUM(BD25:BD34) | BE37: =SUM(BE25:BE34) | BF37: =SUM(BF25:BF34) | BG37: =SUM(BG25:BG34) | BH37: =SUM(BH25:BH34) | BI37: =SUM(BI25:BI34) | ... BM37: =SUM(BM25:BM34) | BO37: =SUM(BO25:BO34) | BQ37: =SUM(BQ25:BQ34) | BR37: =SUM(BR25:BR34) | BS37: =SUM(BS25:BS34) | BT37: =SUM(BT25:BT34) | BU37: =SUM(BU25:BU34) | BV37: =SUM(BV25:BV34) | BW37: =SUM(BW25:BW34) | BX37: =SUM(BX25:BX34) | ... CB37: =SUM(CB25:CB34) | CD37: =SUM(CD25:CD34) | CF37: =SUM(CF25:CF34) | CG37: =SUM(CG25:CG34) | CH37: =SUM(CH25:CH34) | CI37: =SUM(CI25:CI34) | CJ37: =SUM(CJ25:CJ34) | CK37: =SUM(CK25:CK34) | CL37: =SUM(CL25:CL34) | CM37: =SUM(CM25:CM34) | ... CQ37: =SUM(CQ25:CQ34) | CS37: =SUM(CS25:CS34)
V40: =V37-5000000 | AK40: =AK37-(Y32)+'2D. Crowd Funding'!G40 | AZ40: =AZ37-AN32 | BO40: =BO37-BC32 | CD40: =CD37-BR32 | CS40: =CS37-CG32
T41: Core Model | V41: =V25+V29+V26+V28 | AI41: Core Model | AK41: =AK25+AK29+AK26+AK28+'2D. Crowd Funding'!G40 | AX41: Core Model | AZ41: =AZ25+AZ29+AZ26+AZ28 | BM41: Core Model | BO41: =BO25+BO29+BO26+BO28 | CB41: Core Model | CD41: =CD25+CD29+CD26+CD28 | CQ41: Core Model | CS41: =CS25+CS29+CS26+CS28
B42: Cash Disbursements
B43: ● | C43: People Cost: Salaries, ER Payroll Taxes and EE Benefits | I43: ='6A. Pre-Launch Exps. - Roll-Up'!K35 | J43: ='6A. Pre-Launch Exps. - Roll-Up'!L35 | K43: ='6A. Pre-Launch Exps. - Roll-Up'!M35 | L43: ='6A. Pre-Launch Exps. - Roll-Up'!N35 | M43: ='6A. Pre-Launch Exps. - Roll-Up'!O35 | N43: ='6A. Pre-Launch Exps. - Roll-Up'!P35 | O43: ='6A. Pre-Launch Exps. - Roll-Up'!Q35 | P43: ='6A. Pre-Launch Exps. - Roll-Up'!R35 | ... T43: ='6A. Pre-Launch Exps. - Roll-Up'!V35 | V43: =SUM(I43:T43) | X43: ='4A. Tel. - Exps. & OI x Month'!$L41 | Y43: ='4A. Tel. - Exps. & OI x Month'!$M41 | Z43: ='4A. Tel. - Exps. & OI x Month'!$N41 | AA43: ='4A. Tel. - Exps. & OI x Month'!$O41 | AB43: ='4A. Tel. - Exps. & OI x Month'!$P41 | AC43: ='4A. Tel. - Exps. & OI x Month'!$Q41 | AD43: ='4A. Tel. - Exps. & OI x Month'!$R41 | AE43: ='4A. Tel. - Exps. & OI x Month'!$S41 | AF43: ='4A. Tel. - Exps. & OI x Month'!$T41 | AG43: ='4A. Tel. - Exps. & OI x Month'!$U41 | AH43: ='4A. Tel. - Exps. & OI x Month'!$V41 | AI43: ='4A. Tel. - Exps. & OI x Month'!$W41 | AK43: =SUM(X43:AI43) | AM43: ='4A. Tel. - Exps. & OI x Month'!$L133 | AN43: ='4A. Tel. - Exps. & OI x Month'!$M133 | AO43: ='4A. Tel. - Exps. & OI x Month'!$N133 | AP43: ='4A. Tel. - Exps. & OI x Month'!$O133 | AQ43: ='4A. Tel. - Exps. & OI x Month'!$P133 | AR43: ='4A. Tel. - Exps. & OI x Month'!$Q133 | AS43: ='4A. Tel. - Exps. & OI x Month'!$R133 | AT43: ='4A. Tel. - Exps. & OI x Month'!$S133 | AU43: ='4A. Tel. - Exps. & OI x Month'!$T133 | AV43: ='4A. Tel. - Exps. & OI x Month'!$U133 | AW43: ='4A. Tel. - Exps. & OI x Month'!$V133 | AX43: ='4A. Tel. - Exps. & OI x Month'!$W133 | AZ43: =SUM(AM43:AX43) | BB43: ='4A. Tel. - Exps. & OI x Month'!$L225 | BC43: ='4A. Tel. - Exps. & OI x Month'!$M225 | BD43: ='4A. Tel. - Exps. & OI x Month'!$N225 | BE43: ='4A. Tel. - Exps. & OI x Month'!$O225 | BF43: ='4A. Tel. - Exps. & OI x Month'!$P225 | BG43: ='4A. Tel. - Exps. & OI x Month'!$Q225 | BH43: ='4A. Tel. - Exps. & OI x Month'!$R225 | BI43: ='4A. Tel. - Exps. & OI x Month'!$S225 | BJ43: ='4A. Tel. - Exps. & OI x Month'!$T225 | BK43: ='4A. Tel. - Exps. & OI x Month'!$U225 | BL43: ='4A. Tel. - Exps. & OI x Month'!$V225 | BM43: ='4A. Tel. - Exps. & OI x Month'!$W225 | BO43: =SUM(BB43:BM43) | BQ43: ='4A. Tel. - Exps. & OI x Month'!L317 | BR43: ='4A. Tel. - Exps. & OI x Month'!M317 | BS43: ='4A. Tel. - Exps. & OI x Month'!N317 | BT43: ='4A. Tel. - Exps. & OI x Month'!O317 | BU43: ='4A. Tel. - Exps. & OI x Month'!P317 | BV43: ='4A. Tel. - Exps. & OI x Month'!Q317 | BW43: ='4A. Tel. - Exps. & OI x Month'!R317 | BX43: ='4A. Tel. - Exps. & OI x Month'!S317 | ... CB43: ='4A. Tel. - Exps. & OI x Month'!W317 | CD43: =SUM(BQ43:CB43) | CF43: ='4A. Tel. - Exps. & OI x Month'!L409 | CG43: ='4A. Tel. - Exps. & OI x Month'!M409 | CH43: ='4A. Tel. - Exps. & OI x Month'!N409 | CI43: ='4A. Tel. - Exps. & OI x Month'!O409 | CJ43: ='4A. Tel. - Exps. & OI x Month'!P409 | CK43: ='4A. Tel. - Exps. & OI x Month'!Q409 | CL43: ='4A. Tel. - Exps. & OI x Month'!R409 | CM43: ='4A. Tel. - Exps. & OI x Month'!S409 | ... CQ43: ='4A. Tel. - Exps. & OI x Month'!W409 | CS43: =SUM(CF43:CQ43) | CU43: <--
B44: ● | C44: Legacy Accrued Payroll | I44: ='[3]$25M Investment'!$M$82 | J44: ='[3]$25M Investment'!$M$149 | K44: 0 | L44: 0 | M44: 0 | N44: 0 | O44: 0 | P44: ='[4]$25M Investment'!$M$551 | Q44: 0 | R44: 0 | S44: 0 | T44: 0 | V44: =SUM(I44:T44) | X44: 0 | Y44: 0 | Z44: 0 | AA44: 0 | AB44: 0 | AC44: 0 | AD44: 0 | AE44: 0 | AF44: 0 | AG44: 0 | AH44: 0 | AI44: 0 | AK44: =SUM(X44:AI44) | AM44: 0 | AN44: 0 | AO44: 0 | AP44: 0 | AQ44: 0 | AR44: 0 | AS44: 0 | AT44: 0 | AU44: 0 | AV44: 0 | AW44: 0 | AX44: 0 | AZ44: =SUM(AM44:AX44) | BB44: 0 | BC44: 0 | BD44: 0 | BE44: 0 | BF44: 0 | BG44: 0 | BH44: 0 | BI44: 0 | BJ44: 0 | BK44: 0 | BL44: 0 | BM44: 0 | BO44: =SUM(BB44:BM44) | BQ44: 0 | BR44: 0 | BS44: 0 | BT44: 0 | BU44: 0 | BV44: 0 | BW44: 0 | BX44: 0 | BY44: 0 | BZ44: 0 | CA44: 0 | CB44: 0 | CD44: =SUM(BQ44:CB44) | CF44: 0 | CG44: 0 | CH44: 0 | CI44: 0 | CJ44: 0 | CK44: 0 | CL44: 0 | CM44: 0 | CN44: 0 | CO44: 0 | CP44: 0 | CQ44: 0 | CS44: =SUM(CF44:CQ44)
B45: ● | C45: Other Legacy/Pre-Funding Liabilities, Estimate | I45: ='[3]$25M Investment'!$M$80 | J45: ='[3]$25M Investment'!$M$147 | K45: ='[4]$25M Investment'!$M$214 | L45: ='[4]$25M Investment'!$M$281 | M45: ='[4]$25M Investment'!$M$348 | N45: ='[4]$25M Investment'!$M$415 | O45: ='[4]$25M Investment'!$M$482 | P45: 0 | Q45: 0 | R45: 0 | S45: 0 | T45: 0 | V45: =SUM(I45:T45) | X45: 0 | Y45: 0 | Z45: 0 | AA45: 0 | AB45: 0 | AC45: 0 | AD45: 0 | AE45: 0 | AF45: 0 | AG45: 0 | AH45: 0 | AI45: 0 | AK45: =SUM(X45:AI45) | AM45: 0 | AN45: 0 | AO45: 0 | AP45: 0 | AQ45: 0 | AR45: 0 | AS45: 0 | AT45: 0 | AU45: 0 | AV45: 0 | AW45: 0 | AX45: 0 | AZ45: =SUM(AM45:AX45) | BB45: 0 | BC45: 0 | BD45: 0 | BE45: 0 | BF45: 0 | BG45: 0 | BH45: 0 | BI45: 0 | BJ45: 0 | BK45: 0 | BL45: 0 | BM45: 0 | BO45: =SUM(BB45:BM45) | BQ45: 0 | BR45: 0 | BS45: 0 | BT45: 0 | BU45: 0 | BV45: 0 | BW45: 0 | BX45: 0 | BY45: 0 | BZ45: 0 | CA45: 0 | CB45: 0 | CD45: =SUM(BQ45:CB45) | CF45: 0 | CG45: 0 | CH45: 0 | CI45: 0 | CJ45: 0 | CK45: 0 | CL45: 0 | CM45: 0 | CN45: 0 | CO45: 0 | CP45: 0 | CQ45: 0 | CS45: =SUM(CF45:CQ45)
B46: ● | C46: Strategic Investments | I46: 0 | J46: ='[4]$25M Investment'!$M$150 | K46: ='[4]$25M Investment'!$M$217 | L46: ='[4]$25M Investment'!$M$284 | M46: ='[4]$25M Investment'!$M$351 | N46: ='[4]$25M Investment'!$M$418 | O46: ='[4]$25M Investment'!$M$485 | P46: ='[4]$25M Investment'!$M$552 | Q46: ='[4]$25M Investment'!$M$619 | R46: ='[4]$25M Investment'!$M$686 | S46: ='[4]$25M Investment'!$M$753 | T46: ='[4]$25M Investment'!$M$820 | V46: =SUM(I46:T46) | X46: ='[4]$25M Investment'!$M$820 | Y46: ='[4]$25M Investment'!$M$820 | Z46: ='[4]$25M Investment'!$M$820 | AA46: ='[4]$25M Investment'!$M$820 | AB46: ='[4]$25M Investment'!$M$820 | AC46: ='[4]$25M Investment'!$M$820 | AD46: ='[4]$25M Investment'!$M$820 | AE46: ='[4]$25M Investment'!$M$820 | ... AI46: ='[4]$25M Investment'!$M$820 | AK46: =SUM(X46:AI46) | AM46: ='[4]$25M Investment'!$M$820 | AN46: ='[4]$25M Investment'!$M$820 | AO46: ='[4]$25M Investment'!$M$820 | AP46: ='[4]$25M Investment'!$M$820 | AQ46: ='[4]$25M Investment'!$M$820 | AR46: ='[4]$25M Investment'!$M$820 | AS46: ='[4]$25M Investment'!$M$820 | AT46: ='[4]$25M Investment'!$M$820+10000 | AU46: ='[4]$25M Investment'!$M$820+10000 | AV46: ='[4]$25M Investment'!$M$820+10000 | AW46: ='[4]$25M Investment'!$M$820+10000 | AX46: ='[4]$25M Investment'!$M$820+10000 | AZ46: =SUM(AM46:AX46) | BB46: ='[4]$25M Investment'!$M$820+10000 | BC46: ='[4]$25M Investment'!$M$820+10000 | BD46: ='[4]$25M Investment'!$M$820+10000 | BE46: ='[4]$25M Investment'!$M$820+10000 | BF46: ='[4]$25M Investment'!$M$820+10000 | BG46: ='[4]$25M Investment'!$M$820+10000 | BH46: ='[4]$25M Investment'!$M$820+10000 | BI46: ='[4]$25M Investment'!$M$820+10000 | ... BM46: ='[4]$25M Investment'!$M$820+10000 | BO46: =SUM(BB46:BM46) | BQ46: ='[4]$25M Investment'!$M$820+10000 | BR46: ='[4]$25M Investment'!$M$820+10000 | BS46: ='[4]$25M Investment'!$M$820+10000 | BT46: ='[4]$25M Investment'!$M$820+10000 | BU46: ='[4]$25M Investment'!$M$820+10000 | BV46: ='[4]$25M Investment'!$M$820+10000 | BW46: ='[4]$25M Investment'!$M$820+10000 | BX46: 0 | BY46: 0 | BZ46: 0 | CA46: 0 | CB46: 0 | CD46: =SUM(BQ46:CB46) | CF46: 0 | CG46: 0 | CH46: 0 | CI46: 0 | CJ46: 0 | CK46: 0 | CL46: 0 | CM46: 0 | CN46: 0 | CO46: 0 | CP46: 0 | CQ46: 0 | CS46: =SUM(CF46:CQ46)
B47: ● | C47: Research and Development | I47: ='6A. Pre-Launch Exps. - Roll-Up'!K39 | J47: ='6A. Pre-Launch Exps. - Roll-Up'!L39 | K47: ='6A. Pre-Launch Exps. - Roll-Up'!M39 | L47: ='6A. Pre-Launch Exps. - Roll-Up'!N39 | M47: ='6A. Pre-Launch Exps. - Roll-Up'!O39 | N47: ='6A. Pre-Launch Exps. - Roll-Up'!P39 | O47: ='6A. Pre-Launch Exps. - Roll-Up'!Q39 | P47: ='6A. Pre-Launch Exps. - Roll-Up'!R39 | ... T47: ='6A. Pre-Launch Exps. - Roll-Up'!V39 | V47: =SUM(I47:T47) | X47: ='4A. Tel. - Exps. & OI x Month'!$L45 | Y47: ='4A. Tel. - Exps. & OI x Month'!$M45 | Z47: ='4A. Tel. - Exps. & OI x Month'!$N45 | AA47: ='4A. Tel. - Exps. & OI x Month'!$O45 | AB47: ='4A. Tel. - Exps. & OI x Month'!$P45 | AC47: ='4A. Tel. - Exps. & OI x Month'!$Q45 | AD47: ='4A. Tel. - Exps. & OI x Month'!$R45 | AE47: ='4A. Tel. - Exps. & OI x Month'!$S45 | AF47: ='4A. Tel. - Exps. & OI x Month'!T45 | AG47: ='4A. Tel. - Exps. & OI x Month'!$U45 | AH47: ='4A. Tel. - Exps. & OI x Month'!$V45 | AI47: ='4A. Tel. - Exps. & OI x Month'!$W45 | AK47: =SUM(X47:AI47) | AM47: ='4A. Tel. - Exps. & OI x Month'!L137 | AN47: ='4A. Tel. - Exps. & OI x Month'!M137 | AO47: ='4A. Tel. - Exps. & OI x Month'!N137 | AP47: ='4A. Tel. - Exps. & OI x Month'!O137 | AQ47: ='4A. Tel. - Exps. & OI x Month'!P137 | AR47: ='4A. Tel. - Exps. & OI x Month'!Q137 | AS47: ='4A. Tel. - Exps. & OI x Month'!R137 | AT47: ='4A. Tel. - Exps. & OI x Month'!S137 | ... AX47: ='4A. Tel. - Exps. & OI x Month'!W137 | AZ47: =SUM(AM47:AX47) | BB47: ='4A. Tel. - Exps. & OI x Month'!L229 | BC47: ='4A. Tel. - Exps. & OI x Month'!M229 | BD47: ='4A. Tel. - Exps. & OI x Month'!N229 | BE47: ='4A. Tel. - Exps. & OI x Month'!O229 | BF47: ='4A. Tel. - Exps. & OI x Month'!P229 | BG47: ='4A. Tel. - Exps. & OI x Month'!Q229 | BH47: ='4A. Tel. - Exps. & OI x Month'!R229 | BI47: ='4A. Tel. - Exps. & OI x Month'!S229 | ... BM47: ='4A. Tel. - Exps. & OI x Month'!W229 | BO47: =SUM(BB47:BM47) | BQ47: ='4A. Tel. - Exps. & OI x Month'!L321 | BR47: ='4A. Tel. - Exps. & OI x Month'!M321 | BS47: ='4A. Tel. - Exps. & OI x Month'!N321 | BT47: ='4A. Tel. - Exps. & OI x Month'!O321 | BU47: ='4A. Tel. - Exps. & OI x Month'!P321 | BV47: ='4A. Tel. - Exps. & OI x Month'!Q321 | BW47: ='4A. Tel. - Exps. & OI x Month'!R321 | BX47: ='4A. Tel. - Exps. & OI x Month'!S321 | ... CB47: ='4A. Tel. - Exps. & OI x Month'!W321 | CD47: =SUM(BQ47:CB47) | CF47: ='4A. Tel. - Exps. & OI x Month'!L413 | CG47: ='4A. Tel. - Exps. & OI x Month'!M413 | CH47: ='4A. Tel. - Exps. & OI x Month'!N413 | CI47: ='4A. Tel. - Exps. & OI x Month'!O413 | CJ47: ='4A. Tel. - Exps. & OI x Month'!P413 | CK47: ='4A. Tel. - Exps. & OI x Month'!Q413 | CL47: ='4A. Tel. - Exps. & OI x Month'!R413 | CM47: ='4A. Tel. - Exps. & OI x Month'!S413 | ... CQ47: ='4A. Tel. - Exps. & OI x Month'!W413 | CS47: =SUM(CF47:CQ47)
B48: ● | C48: Pre-Launch Telephone Inventory Investment | I48: ='6A. Pre-Launch Exps. - Roll-Up'!K41 | J48: ='6A. Pre-Launch Exps. - Roll-Up'!L41 | K48: ='6A. Pre-Launch Exps. - Roll-Up'!M41 | L48: ='6A. Pre-Launch Exps. - Roll-Up'!N41 | M48: ='6A. Pre-Launch Exps. - Roll-Up'!O41 | N48: ='6A. Pre-Launch Exps. - Roll-Up'!P41 | O48: ='6A. Pre-Launch Exps. - Roll-Up'!Q41 | P48: ='6A. Pre-Launch Exps. - Roll-Up'!R41 | ... T48: ='6A. Pre-Launch Exps. - Roll-Up'!V41 | V48: =SUM(I48:T48) | X48: 0 | Y48: 0 | Z48: 0 | AA48: 0 | AB48: 0 | AC48: 0 | AD48: 0 | AE48: 0 | AF48: 0 | AG48: 0 | AH48: 0 | AI48: 0 | AK48: =SUM(X48:AI48) | AM48: 0 | AN48: 0 | AO48: 0 | AP48: 0 | AQ48: 0 | AR48: 0 | AS48: 0 | AT48: 0 | AU48: 0 | AV48: 0 | AW48: 0 | AX48: 0 | AZ48: =SUM(AM48:AX48) | BB48: 0 | BC48: 0 | BD48: 0 | BE48: 0 | BF48: 0 | BG48: 0 | BH48: 0 | BI48: 0 | BJ48: 0 | BK48: 0 | BL48: 0 | BM48: 0 | BO48: =SUM(BB48:BM48) | BQ48: 0 | BR48: 0 | BS48: 0 | BT48: 0 | BU48: 0 | BV48: 0 | BW48: 0 | BX48: 0 | BY48: 0 | BZ48: 0 | CA48: 0 | CB48: 0 | CD48: =SUM(BQ48:CB48) | CF48: 0 | CG48: 0 | CH48: 0 | CI48: 0 | CJ48: 0 | CK48: 0 | CL48: 0 | CM48: 0 | CN48: 0 | CO48: 0 | CP48: 0 | CQ48: 0 | CS48: =SUM(CF48:CQ48)
B49: ● | C49: Post-Lauch Telephone Inventory Purchases | I49: ='2C. Inventory Cash Disburse.'!G40 | J49: ='2C. Inventory Cash Disburse.'!H40 | K49: ='2C. Inventory Cash Disburse.'!I40 | L49: ='2C. Inventory Cash Disburse.'!M40 | M49: ='2C. Inventory Cash Disburse.'!N40 | N49: ='2C. Inventory Cash Disburse.'!O40 | O49: ='2C. Inventory Cash Disburse.'!P40 | P49: ='2C. Inventory Cash Disburse.'!Q40 | Q49: ='2C. Inventory Cash Disburse.'!R40 | R49: ='2C. Inventory Cash Disburse.'!S40 | S49: ='2C. Inventory Cash Disburse.'!T40 | T49: ='2C. Inventory Cash Disburse.'!U40 | V49: =SUM(I49:T49) | X49: ='2C. Inventory Cash Disburse.'!Y40 | Y49: ='2C. Inventory Cash Disburse.'!Z40 | Z49: ='2C. Inventory Cash Disburse.'!AA40 | AA49: ='2C. Inventory Cash Disburse.'!AB40 | AB49: ='2C. Inventory Cash Disburse.'!AC40 | AC49: ='2C. Inventory Cash Disburse.'!AD40 | AD49: ='2C. Inventory Cash Disburse.'!AE40 | AE49: ='2C. Inventory Cash Disburse.'!AF40 | ... AI49: ='2C. Inventory Cash Disburse.'!AJ40 | AK49: =SUM(X49:AI49) | AM49: ='2C. Inventory Cash Disburse.'!AN40 | AN49: ='2C. Inventory Cash Disburse.'!AO40 | AO49: ='2C. Inventory Cash Disburse.'!AP40 | AP49: ='2C. Inventory Cash Disburse.'!AQ40 | AQ49: ='2C. Inventory Cash Disburse.'!AR40 | AR49: ='2C. Inventory Cash Disburse.'!AS40 | AS49: ='2C. Inventory Cash Disburse.'!AT40 | AT49: ='2C. Inventory Cash Disburse.'!AU40 | ... AX49: ='2C. Inventory Cash Disburse.'!AY40 | AZ49: =SUM(AM49:AX49) | BB49: ='2C. Inventory Cash Disburse.'!BC40 | BC49: ='2C. Inventory Cash Disburse.'!BD40 | BD49: ='2C. Inventory Cash Disburse.'!BE40 | BE49: ='2C. Inventory Cash Disburse.'!BF40 | BF49: ='2C. Inventory Cash Disburse.'!BG40 | BG49: ='2C. Inventory Cash Disburse.'!BH40 | BH49: ='2C. Inventory Cash Disburse.'!BI40 | BI49: ='2C. Inventory Cash Disburse.'!BJ40 | ... BM49: ='2C. Inventory Cash Disburse.'!BN40 | BO49: =SUM(BB49:BM49) | BQ49: ='2C. Inventory Cash Disburse.'!BR40 | BR49: ='2C. Inventory Cash Disburse.'!BS40 | BS49: ='2C. Inventory Cash Disburse.'!BT40 | BT49: ='2C. Inventory Cash Disburse.'!BU40 | BU49: ='2C. Inventory Cash Disburse.'!BV40 | BV49: ='2C. Inventory Cash Disburse.'!BW40 | BW49: ='2C. Inventory Cash Disburse.'!BX40 | BX49: ='2C. Inventory Cash Disburse.'!BY40 | ... CB49: ='2C. Inventory Cash Disburse.'!CC40 | CD49: =SUM(BQ49:CB49) | CF49: ='2C. Inventory Cash Disburse.'!CG40 | CG49: ='2C. Inventory Cash Disburse.'!CH40 | CH49: ='2C. Inventory Cash Disburse.'!CI40 | CI49: ='2C. Inventory Cash Disburse.'!CJ40 | CJ49: ='2C. Inventory Cash Disburse.'!CK40 | CK49: ='2C. Inventory Cash Disburse.'!CL40 | CL49: ='2C. Inventory Cash Disburse.'!CM40 | CM49: ='2C. Inventory Cash Disburse.'!CN40 | ... CQ49: ='2C. Inventory Cash Disburse.'!CR40 | CS49: =SUM(CF49:CQ49)
B50: ● | C50: Sales and Marketing | I50: ='6A. Pre-Launch Exps. - Roll-Up'!K53 | J50: ='6A. Pre-Launch Exps. - Roll-Up'!L53 | K50: ='6A. Pre-Launch Exps. - Roll-Up'!M53 | L50: ='6A. Pre-Launch Exps. - Roll-Up'!N53 | M50: ='6A. Pre-Launch Exps. - Roll-Up'!O53 | N50: ='6A. Pre-Launch Exps. - Roll-Up'!P53 | O50: ='6A. Pre-Launch Exps. - Roll-Up'!Q53 | P50: ='6A. Pre-Launch Exps. - Roll-Up'!R53 | ... T50: ='6A. Pre-Launch Exps. - Roll-Up'!V53 | V50: =SUM(I50:T50) | X50: ='4A. Tel. - Exps. & OI x Month'!$L54 | Y50: ='4A. Tel. - Exps. & OI x Month'!$M54 | Z50: ='4A. Tel. - Exps. & OI x Month'!$N54 | AA50: ='4A. Tel. - Exps. & OI x Month'!$O54 | AB50: ='4A. Tel. - Exps. & OI x Month'!$P54 | AC50: ='4A. Tel. - Exps. & OI x Month'!$Q54 | AD50: ='4A. Tel. - Exps. & OI x Month'!$R54 | AE50: ='4A. Tel. - Exps. & OI x Month'!$S54 | AF50: ='4A. Tel. - Exps. & OI x Month'!$T54 | AG50: ='4A. Tel. - Exps. & OI x Month'!$U54 | AH50: ='4A. Tel. - Exps. & OI x Month'!$V54 | AI50: ='4A. Tel. - Exps. & OI x Month'!$W54 | AK50: =SUM(X50:AI50) | AM50: ='4A. Tel. - Exps. & OI x Month'!L$146 | AN50: ='4A. Tel. - Exps. & OI x Month'!M$146 | AO50: ='4A. Tel. - Exps. & OI x Month'!N$146 | AP50: ='4A. Tel. - Exps. & OI x Month'!O$146 | AQ50: ='4A. Tel. - Exps. & OI x Month'!P$146 | AR50: ='4A. Tel. - Exps. & OI x Month'!Q$146 | AS50: ='4A. Tel. - Exps. & OI x Month'!R$146 | AT50: ='4A. Tel. - Exps. & OI x Month'!S$146 | ... AX50: ='4A. Tel. - Exps. & OI x Month'!W$146 | AZ50: =SUM(AM50:AX50) | BB50: ='4A. Tel. - Exps. & OI x Month'!L238 | BC50: ='4A. Tel. - Exps. & OI x Month'!M238 | BD50: ='4A. Tel. - Exps. & OI x Month'!N238 | BE50: ='4A. Tel. - Exps. & OI x Month'!O238 | BF50: ='4A. Tel. - Exps. & OI x Month'!P238 | BG50: ='4A. Tel. - Exps. & OI x Month'!Q238 | BH50: ='4A. Tel. - Exps. & OI x Month'!R238 | BI50: ='4A. Tel. - Exps. & OI x Month'!S238 | ... BM50: ='4A. Tel. - Exps. & OI x Month'!W238 | BO50: =SUM(BB50:BM50) | BQ50: ='4A. Tel. - Exps. & OI x Month'!L330 | BR50: ='4A. Tel. - Exps. & OI x Month'!M330 | BS50: ='4A. Tel. - Exps. & OI x Month'!N330 | BT50: ='4A. Tel. - Exps. & OI x Month'!O330 | BU50: ='4A. Tel. - Exps. & OI x Month'!P330 | BV50: ='4A. Tel. - Exps. & OI x Month'!Q330 | BW50: ='4A. Tel. - Exps. & OI x Month'!R330 | BX50: ='4A. Tel. - Exps. & OI x Month'!S330 | ... CB50: ='4A. Tel. - Exps. & OI x Month'!W330 | CD50: =SUM(BQ50:CB50) | CF50: ='4A. Tel. - Exps. & OI x Month'!L422 | CG50: ='4A. Tel. - Exps. & OI x Month'!M422 | CH50: ='4A. Tel. - Exps. & OI x Month'!N422 | CI50: ='4A. Tel. - Exps. & OI x Month'!O422 | CJ50: ='4A. Tel. - Exps. & OI x Month'!P422 | CK50: ='4A. Tel. - Exps. & OI x Month'!Q422 | CL50: ='4A. Tel. - Exps. & OI x Month'!R422 | CM50: ='4A. Tel. - Exps. & OI x Month'!S422 | ... CQ50: ='4A. Tel. - Exps. & OI x Month'!W422 | CS50: =SUM(CF50:CQ50)
B51: ● | C51: Occupancy | I51: ='6A. Pre-Launch Exps. - Roll-Up'!K62 | J51: ='6A. Pre-Launch Exps. - Roll-Up'!L62 | K51: ='6A. Pre-Launch Exps. - Roll-Up'!M62 | L51: ='6A. Pre-Launch Exps. - Roll-Up'!N62 | M51: ='6A. Pre-Launch Exps. - Roll-Up'!O62 | N51: ='6A. Pre-Launch Exps. - Roll-Up'!P62 | O51: ='6A. Pre-Launch Exps. - Roll-Up'!Q62 | P51: ='6A. Pre-Launch Exps. - Roll-Up'!R62 | ... T51: ='6A. Pre-Launch Exps. - Roll-Up'!V62 | V51: =SUM(I51:T51) | X51: ='4A. Tel. - Exps. & OI x Month'!$L63 | Y51: ='4A. Tel. - Exps. & OI x Month'!$M63 | Z51: ='4A. Tel. - Exps. & OI x Month'!$N63 | AA51: ='4A. Tel. - Exps. & OI x Month'!$O63 | AB51: ='4A. Tel. - Exps. & OI x Month'!$P63 | AC51: ='4A. Tel. - Exps. & OI x Month'!$Q63 | AD51: ='4A. Tel. - Exps. & OI x Month'!$R63 | AE51: ='4A. Tel. - Exps. & OI x Month'!$S63 | AF51: ='4A. Tel. - Exps. & OI x Month'!$T63 | AG51: ='4A. Tel. - Exps. & OI x Month'!$U63 | AH51: ='4A. Tel. - Exps. & OI x Month'!$V63 | AI51: ='4A. Tel. - Exps. & OI x Month'!$W63 | AK51: =SUM(X51:AI51) | AM51: ='4A. Tel. - Exps. & OI x Month'!L155 | AN51: ='4A. Tel. - Exps. & OI x Month'!M155 | AO51: ='4A. Tel. - Exps. & OI x Month'!N155 | AP51: ='4A. Tel. - Exps. & OI x Month'!O155 | AQ51: ='4A. Tel. - Exps. & OI x Month'!P155 | AR51: ='4A. Tel. - Exps. & OI x Month'!Q155 | AS51: ='4A. Tel. - Exps. & OI x Month'!R155 | AT51: ='4A. Tel. - Exps. & OI x Month'!S155 | ... AX51: ='4A. Tel. - Exps. & OI x Month'!W155 | AZ51: =SUM(AM51:AX51) | BB51: ='4A. Tel. - Exps. & OI x Month'!L247 | BC51: ='4A. Tel. - Exps. & OI x Month'!M247 | BD51: ='4A. Tel. - Exps. & OI x Month'!N247 | BE51: ='4A. Tel. - Exps. & OI x Month'!O247 | BF51: ='4A. Tel. - Exps. & OI x Month'!P247 | BG51: ='4A. Tel. - Exps. & OI x Month'!Q247 | BH51: ='4A. Tel. - Exps. & OI x Month'!R247 | BI51: ='4A. Tel. - Exps. & OI x Month'!S247 | ... BM51: ='4A. Tel. - Exps. & OI x Month'!W247 | BO51: =SUM(BB51:BM51) | BQ51: ='4A. Tel. - Exps. & OI x Month'!L339 | BR51: ='4A. Tel. - Exps. & OI x Month'!M339 | BS51: ='4A. Tel. - Exps. & OI x Month'!N339 | BT51: ='4A. Tel. - Exps. & OI x Month'!O339 | BU51: ='4A. Tel. - Exps. & OI x Month'!P339 | BV51: ='4A. Tel. - Exps. & OI x Month'!Q339 | BW51: ='4A. Tel. - Exps. & OI x Month'!R339 | BX51: ='4A. Tel. - Exps. & OI x Month'!S339 | ... CB51: ='4A. Tel. - Exps. & OI x Month'!W339 | CD51: =SUM(BQ51:CB51) | CF51: ='4A. Tel. - Exps. & OI x Month'!L431 | CG51: ='4A. Tel. - Exps. & OI x Month'!M431 | CH51: ='4A. Tel. - Exps. & OI x Month'!N431 | CI51: ='4A. Tel. - Exps. & OI x Month'!O431 | CJ51: ='4A. Tel. - Exps. & OI x Month'!P431 | CK51: ='4A. Tel. - Exps. & OI x Month'!Q431 | CL51: ='4A. Tel. - Exps. & OI x Month'!R431 | CM51: ='4A. Tel. - Exps. & OI x Month'!S431 | ... CQ51: ='4A. Tel. - Exps. & OI x Month'!W431 | CS51: =SUM(CF51:CQ51)
B52: ● | C52: General and Administrative | I52: ='6A. Pre-Launch Exps. - Roll-Up'!K87 | J52: ='6A. Pre-Launch Exps. - Roll-Up'!L87 | K52: ='6A. Pre-Launch Exps. - Roll-Up'!M87 | L52: ='6A. Pre-Launch Exps. - Roll-Up'!N87 | M52: ='6A. Pre-Launch Exps. - Roll-Up'!O87 | N52: ='6A. Pre-Launch Exps. - Roll-Up'!P87 | O52: ='6A. Pre-Launch Exps. - Roll-Up'!Q87 | P52: ='6A. Pre-Launch Exps. - Roll-Up'!R87 | ... T52: ='6A. Pre-Launch Exps. - Roll-Up'!V87 | V52: =SUM(I52:T52) | X52: ='4A. Tel. - Exps. & OI x Month'!$L84 | Y52: ='4A. Tel. - Exps. & OI x Month'!$M84 | Z52: ='4A. Tel. - Exps. & OI x Month'!$N84 | AA52: ='4A. Tel. - Exps. & OI x Month'!$O84 | AB52: ='4A. Tel. - Exps. & OI x Month'!$P84 | AC52: ='4A. Tel. - Exps. & OI x Month'!$Q84 | AD52: ='4A. Tel. - Exps. & OI x Month'!$R84 | AE52: ='4A. Tel. - Exps. & OI x Month'!$S84 | AF52: ='4A. Tel. - Exps. & OI x Month'!$T84 | AG52: ='4A. Tel. - Exps. & OI x Month'!$U84 | AH52: ='4A. Tel. - Exps. & OI x Month'!$V84 | AI52: ='4A. Tel. - Exps. & OI x Month'!$W84 | AK52: =SUM(X52:AI52) | AM52: ='4A. Tel. - Exps. & OI x Month'!L176 | AN52: ='4A. Tel. - Exps. & OI x Month'!M176 | AO52: ='4A. Tel. - Exps. & OI x Month'!N176 | AP52: ='4A. Tel. - Exps. & OI x Month'!O176 | AQ52: ='4A. Tel. - Exps. & OI x Month'!P176 | AR52: ='4A. Tel. - Exps. & OI x Month'!Q176 | AS52: ='4A. Tel. - Exps. & OI x Month'!R176 | AT52: ='4A. Tel. - Exps. & OI x Month'!S176 | ... AX52: ='4A. Tel. - Exps. & OI x Month'!W176 | AZ52: =SUM(AM52:AX52) | BB52: ='4A. Tel. - Exps. & OI x Month'!L268 | BC52: ='4A. Tel. - Exps. & OI x Month'!M268 | BD52: ='4A. Tel. - Exps. & OI x Month'!N268 | BE52: ='4A. Tel. - Exps. & OI x Month'!O268 | BF52: ='4A. Tel. - Exps. & OI x Month'!P268 | BG52: ='4A. Tel. - Exps. & OI x Month'!Q268 | BH52: ='4A. Tel. - Exps. & OI x Month'!R268 | BI52: ='4A. Tel. - Exps. & OI x Month'!S268 | ... BM52: ='4A. Tel. - Exps. & OI x Month'!W268 | BO52: =SUM(BB52:BM52) | BQ52: ='4A. Tel. - Exps. & OI x Month'!L360 | BR52: ='4A. Tel. - Exps. & OI x Month'!M360 | BS52: ='4A. Tel. - Exps. & OI x Month'!N360 | BT52: ='4A. Tel. - Exps. & OI x Month'!O360 | BU52: ='4A. Tel. - Exps. & OI x Month'!P360 | BV52: ='4A. Tel. - Exps. & OI x Month'!Q360 | BW52: ='4A. Tel. - Exps. & OI x Month'!R360 | BX52: ='4A. Tel. - Exps. & OI x Month'!S360 | ... CB52: ='4A. Tel. - Exps. & OI x Month'!W360 | CD52: =SUM(BQ52:CB52) | CF52: ='4A. Tel. - Exps. & OI x Month'!L452 | CG52: ='4A. Tel. - Exps. & OI x Month'!M452 | CH52: ='4A. Tel. - Exps. & OI x Month'!N452 | CI52: ='4A. Tel. - Exps. & OI x Month'!O452 | CJ52: ='4A. Tel. - Exps. & OI x Month'!P452 | CK52: ='4A. Tel. - Exps. & OI x Month'!Q452 | CL52: ='4A. Tel. - Exps. & OI x Month'!R452 | CM52: ='4A. Tel. - Exps. & OI x Month'!S452 | ... CQ52: ='4A. Tel. - Exps. & OI x Month'!W452 | CS52: =SUM(CF52:CQ52)
B53: ● | C53: Customer Rewards | I53: 0 | J53: 0 | K53: 0 | L53: 0 | M53: 0 | N53: 0 | O53: 0 | P53: 0 | Q53: 0 | R53: 0 | S53: 0 | T53: 0 | V53: =SUM(I53:T53) | X53: ='3B. Tel. - Rev. Detail x Month'!$J300 | Y53: ='3B. Tel. - Rev. Detail x Month'!$K300 | Z53: ='3B. Tel. - Rev. Detail x Month'!$L300 | AA53: ='3B. Tel. - Rev. Detail x Month'!$M300 | AB53: ='3B. Tel. - Rev. Detail x Month'!$N300 | AC53: ='3B. Tel. - Rev. Detail x Month'!$O300 | AD53: ='3B. Tel. - Rev. Detail x Month'!$P300 | AE53: ='3B. Tel. - Rev. Detail x Month'!$Q300 | AF53: ='3B. Tel. - Rev. Detail x Month'!$R300 | AG53: ='3B. Tel. - Rev. Detail x Month'!$S300 | AH53: ='3B. Tel. - Rev. Detail x Month'!$T300 | AI53: ='3B. Tel. - Rev. Detail x Month'!$U300 | AK53: =SUM(X53:AI53) | AM53: ='3B. Tel. - Rev. Detail x Month'!J332 | AN53: ='3B. Tel. - Rev. Detail x Month'!K332 | AO53: ='3B. Tel. - Rev. Detail x Month'!L332 | AP53: ='3B. Tel. - Rev. Detail x Month'!M332 | AQ53: ='3B. Tel. - Rev. Detail x Month'!N332 | AR53: ='3B. Tel. - Rev. Detail x Month'!O332 | AS53: ='3B. Tel. - Rev. Detail x Month'!P332 | AT53: ='3B. Tel. - Rev. Detail x Month'!Q332 | ... AX53: ='3B. Tel. - Rev. Detail x Month'!U332 | AZ53: =SUM(AM53:AX53) | BB53: ='3B. Tel. - Rev. Detail x Month'!J364 | BC53: ='3B. Tel. - Rev. Detail x Month'!K364 | BD53: ='3B. Tel. - Rev. Detail x Month'!L364 | BE53: ='3B. Tel. - Rev. Detail x Month'!M364 | BF53: ='3B. Tel. - Rev. Detail x Month'!N364 | BG53: ='3B. Tel. - Rev. Detail x Month'!O364 | BH53: ='3B. Tel. - Rev. Detail x Month'!P364 | BI53: ='3B. Tel. - Rev. Detail x Month'!Q364 | ... BM53: ='3B. Tel. - Rev. Detail x Month'!U364 | BO53: =SUM(BB53:BM53) | BQ53: ='3B. Tel. - Rev. Detail x Month'!J396 | BR53: ='3B. Tel. - Rev. Detail x Month'!K396 | BS53: ='3B. Tel. - Rev. Detail x Month'!L396 | BT53: ='3B. Tel. - Rev. Detail x Month'!M396 | BU53: ='3B. Tel. - Rev. Detail x Month'!N396 | BV53: ='3B. Tel. - Rev. Detail x Month'!O396 | BW53: ='3B. Tel. - Rev. Detail x Month'!P396 | BX53: ='3B. Tel. - Rev. Detail x Month'!Q396 | ... CB53: ='3B. Tel. - Rev. Detail x Month'!U396 | CD53: =SUM(BQ53:CB53) | CF53: ='3B. Tel. - Rev. Detail x Month'!J428 | CG53: ='3B. Tel. - Rev. Detail x Month'!K428 | CH53: ='3B. Tel. - Rev. Detail x Month'!L428 | CI53: ='3B. Tel. - Rev. Detail x Month'!M428 | CJ53: ='3B. Tel. - Rev. Detail x Month'!N428 | CK53: ='3B. Tel. - Rev. Detail x Month'!O428 | CL53: ='3B. Tel. - Rev. Detail x Month'!P428 | CM53: ='3B. Tel. - Rev. Detail x Month'!Q428 | ... CQ53: ='3B. Tel. - Rev. Detail x Month'!U428 | CS53: =SUM(CF53:CQ53)
B54: ● | C54: Melanie Salvador Commission (paid based on tranches) | I54: 0 | J54: ='[4]$25M Investment'!$H$153 | K54: 0 | L54: 0 | M54: 250000 | Q54: 0 | R54: 0 | S54: 0 | T54: 0 | V54: =SUM(I54:T54) | X54: 0 | Y54: 0 | Z54: 0 | AA54: 0 | AB54: 0 | AC54: 0 | AD54: 0 | AE54: 0 | AF54: 0 | AG54: 0 | AH54: 0 | AI54: 0 | AK54: =SUM(X54:AI54) | AM54: 0 | AN54: 0 | AO54: 0 | AP54: 0 | AQ54: 0 | AR54: 0 | AS54: 0 | AT54: 0 | AU54: 0 | AV54: 0 | AW54: 0 | AX54: 0 | AZ54: =SUM(AM54:AX54) | BB54: 0 | BC54: 0 | BD54: 0 | BE54: 0 | BF54: 0 | BG54: 0 | BH54: 0 | BI54: 0 | BJ54: 0 | BK54: 0 | BL54: 0 | BM54: 0 | BO54: =SUM(BB54:BM54) | BQ54: 0 | BR54: 0 | BS54: 0 | BT54: 0 | BU54: 0 | BV54: 0 | BW54: 0 | BX54: 0 | BY54: 0 | BZ54: 0 | CA54: 0 | CB54: 0 | CD54: =SUM(BQ54:CB54) | CF54: 0 | CG54: 0 | CH54: 0 | CI54: 0 | CJ54: 0 | CK54: 0 | CL54: 0 | CM54: 0 | CN54: 0 | CO54: 0 | CP54: 0 | CQ54: 0 | CS54: =SUM(CF54:CQ54)
