Workbook

Sheet HOW TO USE
A1: PUREBRAIN 5-YEAR FINANCIAL MODEL — USER GUIDE
B3: QUICK START (2 minutes)
B4: Step 1 | C4: Go to ASSUMPTIONS sheet → Cell B5 (gold cell)
B5: Step 2 | C5: Type 1 for Bear, 2 for Base, or 3 for Bull scenario
B6: Step 3 | C6: Every sheet auto-updates. Check INVESTOR DASHBOARD for summary.
B7: That's it. | C7: Change any blue cell on ASSUMPTIONS → all 7 sheets recalculate.
B9: SHEET-BY-SHEET GUIDE
B10: HOW TO USE (this sheet) | C10: You are here. Instructions and reference.
B11: ASSUMPTIONS | C11: The CONTROL PANEL. Every editable input lives here.
B12: YEAR 1 MONTHLY | C12: Month-by-month P&L: Mar 2026 → Feb 2027
B13: YEARS 2-5 QUARTERLY | C13: Quarterly projections: Q1 2027 → Q4 2030
B14: P&L STATEMENT | C14: GAAP-format income statement (annual summary)
B15: UNIT ECONOMICS | C15: LTV, CAC, churn, payback, NRR by tier
B16: INVESTOR DASHBOARD | C16: Executive KPI scorecard — the sheet investors see first
B17: SCENARIO ENGINE | C17: Bull/Base/Bear side-by-side + sensitivity analysis
B19: HOW TO RUN SCENARIOS
B20: Scenario Toggle (fastest) | C20: ASSUMPTIONS → B5. Type 1 (Bear), 2 (Base), or 3 (Bull). Entire model recalculates instantly.
B21: What changes per scenario | C21: Growth multiplier (B6 auto-calculates), monthly sign-up targets (rows 63-74 switch columns), and all downstream MRR/revenue/EBITDA.
B22: Bear = Conservative | C22: 50% slower growth, 6% churn. Dec 2026 MRR: ~$48M. $1B MRR by Q4 2029.
B23: Base = As Modeled | C23: Growth rates as planned, 3.5% churn. Dec 2026 MRR: ~$128M. $1B MRR by Q2 2028.
B24: Bull = Aggressive | C24: 30% faster growth, 3% churn, higher ARPU. Dec 2026 MRR: ~$285M. $1B MRR by Q4 2027.
B25: Custom Scenarios | C25: Override ANY blue cell on ASSUMPTIONS: pricing, churn %, tier mix, headcount, compute costs, marketing %, CAC. Model recalculates.
B26: Side-by-Side Comparison | C26: SCENARIO ENGINE sheet shows all 3 scenarios with delta columns showing the dollar difference.
B27: Sensitivity Table | C27: SCENARIO ENGINE rows 25-35: matrix showing Dec 2026 MRR at different churn × growth combinations.
B28: Tornado Chart Data | C28: SCENARIO ENGINE rows 38+: ranks the top 6 revenue drivers by impact magnitude.
B30: WHAT CAN I CHANGE?
B31: Tier Pricing → B10-B12 | C31: Awakened $197, Partnered $579, Unified $1,089
B32: Tier Mix % → C10-C12 | C32: 72% / 20% / 8% — must sum to 100%
B33: Monthly Churn Rates → D10-D12 | C33: 4.5% / 3.0% / 2.0% per tier
B34: Scenario Selector → B5 | C34: 1=Bear, 2=Base, 3=Bull
B35: Enterprise Pipeline → B29-D34 | C35: Client count × avg contract per stage
B36: Headcount Plan → B29-D35 (Headcount section) | C36: Staff count per growth stage
B37: AI Compute Cost/User → C39-C44 | C37: Cost per user at each scale level
B38: Marketing % of MRR → B48-B52 | C38: Marketing spend as % of revenue
B39: CAC by Stage → C48-C52 | C39: Customer acquisition cost at each stage
B40: NRR by Stage → D48-D52 | C40: Net revenue retention (upgrades vs churn)
B41: Monthly Sign-Up Targets → B63-D74 | C41: Bear/Base/Bull new user targets per month
B42: Payment Processing Rate → B59 | C42: Default 3%
B44: COLOR LEGEND
B45: Blue cells | C45: Editable inputs — change these freely
...

Sheet ASSUMPTIONS
A1: PUREBRAIN.AI — 5-YEAR FINANCIAL MODEL | ASSUMPTIONS & CONTROL PANEL
A2: Blue cells = EDITABLE INPUTS | White/Gray cells = CALCULATED | Last Updated: March 16, 2026
A4: SCENARIO SELECTOR
A5: Active Scenario (1=Bear, 2=Base, 3=Bull) | B5: 2 | C5: ← Change this cell | E5: 1 = Bear Case | F5: 2 = Base Case | G5: 3 = Bull Case
A6: Scenario Growth Multiplier (auto-calc) | B6: =CHOOSE(B5,0.67,1.00,1.40) | C6: 0.67 Bear | 1.00 Base | 1.40 Bull
A8: PRICING & TIER DISTRIBUTION
A9: Tier | B9: Monthly Price | C9: Tier Mix % | D9: Monthly Churn % | E9: Avg Life (months) | F9: Avg Life Calc | G9: LTV | H9: LTV Calc
A10: Awakened | B10: 197 | C10: 0.72 | D10: 0.045 | E10: =IFERROR(1/D10,0) | F10: =ROUND(E10,1) | G10: =B10*E10 | H10: =ROUND(G10,0)
A11: Partnered | B11: 579 | C11: 0.2 | D11: 0.03 | E11: =IFERROR(1/D11,0) | F11: =ROUND(E11,1) | G11: =B11*E11 | H11: =ROUND(G11,0)
A12: Unified | B12: 1089 | C12: 0.08 | D12: 0.02 | E12: =IFERROR(1/D12,0) | F12: =ROUND(E12,1) | G12: =B12*E12 | H12: =ROUND(G12,0)
A13: Mix Total (must = 100%) | B13: =SUM(C10:C12) | C13: =IF(ABS(B13-1)<0.001,"✓ VALID","⚠ FIX MIX")
A15: ENTERPRISE PRICING & CLIENT ASSUMPTIONS
A16: Scale Stage | B16: User Count | C16: # Enterprise Clients | D16: Price/Client/Mo | E16: Enterprise MRR | F16: Enterprise Churn
A17: MVP | B17: 100 | C17: 2 | D17: 10000 | E17: =C17*D17 | F17: 0.015
A18: 1K Users | B18: 1000 | C18: 5 | D18: 10000 | E18: =C18*D18 | F18: 0.015
A19: 10K Users | B19: 10000 | C19: 25 | D19: 12000 | E19: =C19*D19 | F19: 0.015
A20: 100K Users | B20: 100000 | C20: 150 | D20: 15000 | E20: =C20*D20 | F20: 0.015
A21: 1M Users | B21: 1000000 | C21: 1000 | D21: 18000 | E21: =C21*D21 | F21: 0.015
A22: 5M+ Users | B22: 5000000 | C22: 5000 | D22: 20000 | E22: =C22*D22 | F22: 0.015
A24: BLENDED CONSUMER ARPU (auto-calculated from tier mix & pricing)
A25: Blended Consumer ARPU | B25: =B10*C10+B11*C11+B12*C12 | C25: Weighted avg of tier prices × tier mix
A27: HEADCOUNT & PAYROLL ASSUMPTIONS
A28: Stage | B28: Total Users | C28: Headcount | D28: Avg Salary/Mo | E28: Total Payroll/Mo | F28: $/User
A29: Launch | B29: 100 | C29: 48 | D29: 10000 | E29: =C29*D29 | F29: =IFERROR(E29/B29,0)
A30: 1K Users | B30: 1000 | C30: 55 | D30: 10000 | E30: =C30*D30 | F30: =IFERROR(E30/B30,0)
A31: 10K Users | B31: 10000 | C31: 65 | D31: 10000 | E31: =C31*D31 | F31: =IFERROR(E31/B31,0)
A32: 100K | B32: 100000 | C32: 80 | D32: 10000 | E32: =C32*D32 | F32: =IFERROR(E32/B32,0)
A33: 500K | B33: 500000 | C33: 92 | D33: 10000 | E33: =C33*D33 | F33: =IFERROR(E33/B33,0)
A34: 1M+ | B34: 1000000 | C34: 98 | D34: 10000 | E34: =C34*D34 | F34: =IFERROR(E34/B34,0)
A35: Hard Cap | B35: 9999999 | C35: 100 | D35: 10000 | E35: =C35*D35 | F35: =IFERROR(E35/B35,0)
A37: AI COMPUTE COST PER USER/MONTH (economies of scale)
A38: Scale Stage | B38: Total Users | C38: Cost/User/Mo | D38: % of ARPU
A39: 100 users | B39: 100 | C39: 25 | D39: =IFERROR(C39/ASSUMPTIONS!$B$25,0)
A40: 1K users | B40: 1000 | C40: 18 | D40: =IFERROR(C40/ASSUMPTIONS!$B$25,0)
A41: 10K users | B41: 10000 | C41: 12 | D41: =IFERROR(C41/ASSUMPTIONS!$B$25,0)
A42: 100K users | B42: 100000 | C42: 7 | D42: =IFERROR(C42/ASSUMPTIONS!$B$25,0)
A43: 1M users | B43: 1000000 | C43: 3.5 | D43: =IFERROR(C43/ASSUMPTIONS!$B$25,0)
A44: 5M+ users | B44: 5000000 | C44: 2.4 | D44: =IFERROR(C44/ASSUMPTIONS!$B$25,0)
A46: MARKETING & CAC ASSUMPTIONS
A47: Stage | B47: Marketing % MRR | C47: CAC ($) | D47: NRR
...

Sheet YEAR 1 MONTHLY
A1: PUREBRAIN.AI — YEAR 1 MONTHLY MODEL (Mar 2026 – Feb 2027)
A2: All formulas reference ASSUMPTIONS sheet. Change scenario there to see Bear/Base/Bull.
A4: METRIC | B4: Mar-26 | C4: Apr-26 | D4: May-26 | E4: Jun-26 | F4: Jul-26 | G4: Aug-26 | H4: Sep-26 | I4: Oct-26 | J4: Nov-26 | K4: Dec-26 | L4: Jan-27 | M4: Feb-27 | N4: YEAR 1 TOTAL
A5: SUBSCRIBER ACQUISITION
A6: New Sign-Ups (Scenario) | B6: =ASSUMPTIONS!E63 | C6: =ASSUMPTIONS!E64 | D6: =ASSUMPTIONS!E65 | E6: =ASSUMPTIONS!E66 | F6: =ASSUMPTIONS!E67 | G6: =ASSUMPTIONS!E68 | H6: =ASSUMPTIONS!E69 | I6: =ASSUMPTIONS!E70 | J6: =ASSUMPTIONS!E71 | K6: =ASSUMPTIONS!E72 | L6: =ASSUMPTIONS!E73 | M6: =ASSUMPTIONS!E74 | N6: =SUM(B6:M6)
A7: ACTIVE SUBSCRIBERS BY TIER
A8: Active Awakened Subs | B8: =ROUND(B6*ASSUMPTIONS!C10*(1-ASSUMPTIONS!D10),0) | C8: =ROUND(B8*(1-ASSUMPTIONS!D10)+C6*ASSUMPTIONS!C10,0) | D8: =ROUND(C8*(1-ASSUMPTIONS!D10)+D6*ASSUMPTIONS!C10,0) | E8: =ROUND(D8*(1-ASSUMPTIONS!D10)+E6*ASSUMPTIONS!C10,0) | F8: =ROUND(E8*(1-ASSUMPTIONS!D10)+F6*ASSUMPTIONS!C10,0) | G8: =ROUND(F8*(1-ASSUMPTIONS!D10)+G6*ASSUMPTIONS!C10,0) | H8: =ROUND(G8*(1-ASSUMPTIONS!D10)+H6*ASSUMPTIONS!C10,0) | I8: =ROUND(H8*(1-ASSUMPTIONS!D10)+I6*ASSUMPTIONS!C10,0) | J8: =ROUND(I8*(1-ASSUMPTIONS!D10)+J6*ASSUMPTIONS!C10,0) | K8: =ROUND(J8*(1-ASSUMPTIONS!D10)+K6*ASSUMPTIONS!C10,0) | L8: =ROUND(K8*(1-ASSUMPTIONS!D10)+L6*ASSUMPTIONS!C10,0) | M8: =ROUND(L8*(1-ASSUMPTIONS!D10)+M6*ASSUMPTIONS!C10,0) | N8: =M8
A9: Active Partnered Subs | B9: =ROUND(B6*ASSUMPTIONS!C11*(1-ASSUMPTIONS!D11),0) | C9: =ROUND(B9*(1-ASSUMPTIONS!D11)+C6*ASSUMPTIONS!C11,0) | D9: =ROUND(C9*(1-ASSUMPTIONS!D11)+D6*ASSUMPTIONS!C11,0) | E9: =ROUND(D9*(1-ASSUMPTIONS!D11)+E6*ASSUMPTIONS!C11,0) | F9: =ROUND(E9*(1-ASSUMPTIONS!D11)+F6*ASSUMPTIONS!C11,0) | G9: =ROUND(F9*(1-ASSUMPTIONS!D11)+G6*ASSUMPTIONS!C11,0) | H9: =ROUND(G9*(1-ASSUMPTIONS!D11)+H6*ASSUMPTIONS!C11,0) | I9: =ROUND(H9*(1-ASSUMPTIONS!D11)+I6*ASSUMPTIONS!C11,0) | J9: =ROUND(I9*(1-ASSUMPTIONS!D11)+J6*ASSUMPTIONS!C11,0) | K9: =ROUND(J9*(1-ASSUMPTIONS!D11)+K6*ASSUMPTIONS!C11,0) | L9: =ROUND(K9*(1-ASSUMPTIONS!D11)+L6*ASSUMPTIONS!C11,0) | M9: =ROUND(L9*(1-ASSUMPTIONS!D11)+M6*ASSUMPTIONS!C11,0) | N9: =M9
A10: Active Unified Subs | B10: =ROUND(B6*ASSUMPTIONS!C12*(1-ASSUMPTIONS!D12),0) | C10: =ROUND(B10*(1-ASSUMPTIONS!D12)+C6*ASSUMPTIONS!C12,0) | D10: =ROUND(C10*(1-ASSUMPTIONS!D12)+D6*ASSUMPTIONS!C12,0) | E10: =ROUND(D10*(1-ASSUMPTIONS!D12)+E6*ASSUMPTIONS!C12,0) | F10: =ROUND(E10*(1-ASSUMPTIONS!D12)+F6*ASSUMPTIONS!C12,0) | G10: =ROUND(F10*(1-ASSUMPTIONS!D12)+G6*ASSUMPTIONS!C12,0) | H10: =ROUND(G10*(1-ASSUMPTIONS!D12)+H6*ASSUMPTIONS!C12,0) | I10: =ROUND(H10*(1-ASSUMPTIONS!D12)+I6*ASSUMPTIONS!C12,0) | J10: =ROUND(I10*(1-ASSUMPTIONS!D12)+J6*ASSUMPTIONS!C12,0) | K10: =ROUND(J10*(1-ASSUMPTIONS!D12)+K6*ASSUMPTIONS!C12,0) | L10: =ROUND(K10*(1-ASSUMPTIONS!D12)+L6*ASSUMPTIONS!C12,0) | M10: =ROUND(L10*(1-ASSUMPTIONS!D12)+M6*ASSUMPTIONS!C12,0) | N10: =M10
A11: TOTAL Active Subscribers | B11: =B8+B9+B10 | C11: =C8+C9+C10 | D11: =D8+D9+D10 | E11: =E8+E9+E10 | F11: =F8+F9+F10 | G11: =G8+G9+G10 | H11: =H8+H9+H10 | I11: =I8+I9+I10 | ... M11: =M8+M9+M10 | N11: =M11
A12: CONSUMER MRR BY TIER
A13: Awakened MRR | B13: =B8*ASSUMPTIONS!B10 | C13: =C8*ASSUMPTIONS!B10 | D13: =D8*ASSUMPTIONS!B10 | E13: =E8*ASSUMPTIONS!B10 | F13: =F8*ASSUMPTIONS!B10 | G13: =G8*ASSUMPTIONS!B10 | H13: =H8*ASSUMPTIONS!B10 | I13: =I8*ASSUMPTIONS!B10 | J13: =J8*ASSUMPTIONS!B10 | K13: =K8*ASSUMPTIONS!B10 | L13: =L8*ASSUMPTIONS!B10 | M13: =M8*ASSUMPTIONS!B10 | N13: =SUM(B13:M13)
A14: Partnered MRR | B14: =B9*ASSUMPTIONS!B11 | C14: =C9*ASSUMPTIONS!B11 | D14: =D9*ASSUMPTIONS!B11 | E14: =E9*ASSUMPTIONS!B11 | F14: =F9*ASSUMPTIONS!B11 | G14: =G9*ASSUMPTIONS!B11 | H14: =H9*ASSUMPTIONS!B11 | I14: =I9*ASSUMPTIONS!B11 | J14: =J9*ASSUMPTIONS!B11 | K14: =K9*ASSUMPTIONS!B11 | L14: =L9*ASSUMPTIONS!B11 | M14: =M9*ASSUMPTIONS!B11 | N14: =SUM(B14:M14)
A15: Unified MRR | B15: =B10*ASSUMPTIONS!B12 | C15: =C10*ASSUMPTIONS!B12 | D15: =D10*ASSUMPTIONS!B12 | E15: =E10*ASSUMPTIONS!B12 | F15: =F10*ASSUMPTIONS!B12 | G15: =G10*ASSUMPTIONS!B12 | H15: =H10*ASSUMPTIONS!B12 | I15: =I10*ASSUMPTIONS!B12 | J15: =J10*ASSUMPTIONS!B12 | K15: =K10*ASSUMPTIONS!B12 | L15: =L10*ASSUMPTIONS!B12 | M15: =M10*ASSUMPTIONS!B12 | N15: =SUM(B15:M15)
A16: Total Consumer MRR | B16: =B13+B14+B15 | C16: =C13+C14+C15 | D16: =D13+D14+D15 | E16: =E13+E14+E15 | F16: =F13+F14+F15 | G16: =G13+G14+G15 | H16: =H13+H14+H15 | I16: =I13+I14+I15 | ... M16: =M13+M14+M15 | N16: =SUM(B16:M16)
A17: ENTERPRISE MRR
A18: Enterprise Clients | B18: 2 | C18: 5 | D18: 25 | E18: 150 | F18: 200 | G18: 250 | H18: 333 | I18: 433 | J18: 567 | K18: 733 | L18: 933 | M18: 1167 | N18: =M18
A19: Avg Enterprise Price/Mo | B19: 10000 | C19: 10000 | D19: 12000 | E19: 15000 | F19: 15000 | G19: 15000 | H19: 15000 | I19: 15000 | J19: 17000 | K19: 15019 | L19: 15005 | M19: 14993 | N19: =AVERAGE(B19:M19)
A20: Enterprise MRR | B20: =B18*B19 | C20: =C18*C19 | D20: =D18*D19 | E20: =E18*E19 | F20: =F18*F19 | G20: =G18*G19 | H20: =H18*H19 | I20: =I18*I19 | ... M20: =M18*M19 | N20: =SUM(B20:M20)
A21: TOTAL MRR & REVENUE
A22: TOTAL MRR | B22: =B16+B20 | C22: =C16+C20 | D22: =D16+D20 | E22: =E16+E20 | F22: =F16+F20 | G22: =G16+G20 | H22: =H16+H20 | I22: =I16+I20 | ... M22: =M16+M20 | N22: =SUM(B22:M22)
A23: ARR (MRR × 12) | B23: =B22*12 | C23: =C22*12 | D23: =D22*12 | E23: =E22*12 | F23: =F22*12 | G23: =G22*12 | H23: =H22*12 | I23: =I22*12 | ... M23: =M22*12 | N23: =M23
A24: MoM MRR Growth % | B24: N/A | C24: =IFERROR((C22-B22)/B22,0) | D24: =IFERROR((D22-C22)/C22,0) | E24: =IFERROR((E22-D22)/D22,0) | F24: =IFERROR((F22-E22)/E22,0) | G24: =IFERROR((G22-F22)/F22,0) | H24: =IFERROR((H22-G22)/G22,0) | I24: =IFERROR((I22-H22)/H22,0) | J24: =IFERROR((J22-I22)/I22,0) | ... M24: =IFERROR((M22-L22)/L22,0)
A25: MONTHLY EXPENSES (OPEX)
A26: Payroll | B26: 480000 | C26: 550000 | D26: 650000 | E26: 800000 | F26: 800000 | G26: 850000 | H26: 900000 | I26: 920000 | J26: 950000 | K26: 980000 | L26: 1000000 | M26: 1000000 | N26: =SUM(B26:M26)
A27: AI Compute (users × cost/user) | B27: =B11*VLOOKUP(B11,ASSUMPTIONS!$B$60:$C$65,2,TRUE) | C27: =C11*VLOOKUP(C11,ASSUMPTIONS!$B$60:$C$65,2,TRUE) | D27: =D11*VLOOKUP(D11,ASSUMPTIONS!$B$60:$C$65,2,TRUE) | E27: =E11*VLOOKUP(E11,ASSUMPTIONS!$B$60:$C$65,2,TRUE) | F27: =F11*VLOOKUP(F11,ASSUMPTIONS!$B$60:$C$65,2,TRUE) | G27: =G11*VLOOKUP(G11,ASSUMPTIONS!$B$60:$C$65,2,TRUE) | H27: =H11*VLOOKUP(H11,ASSUMPTIONS!$B$60:$C$65,2,TRUE) | I27: =I11*VLOOKUP(I11,ASSUMPTIONS!$B$60:$C$65,2,TRUE) | ... M27: =M11*VLOOKUP(M11,ASSUMPTIONS!$B$60:$C$65,2,TRUE) | N27: =SUM(B27:M27)
A28: Marketing | B28: =B16*0.138 | C28: =C16*0.138 | D28: =D16*0.138 | E28: =E16*0.138 | F28: =F16*0.138 | G28: =G16*0.138 | H28: =H16*0.138 | I28: =I16*0.138 | ... M28: =M16*0.138 | N28: =SUM(B28:M28)
A29: Payment Processing (3% of MRR) | B29: =B22*ASSUMPTIONS!$B$59 | C29: =C22*ASSUMPTIONS!$B$59 | D29: =D22*ASSUMPTIONS!$B$59 | E29: =E22*ASSUMPTIONS!$B$59 | F29: =F22*ASSUMPTIONS!$B$59 | G29: =G22*ASSUMPTIONS!$B$59 | H29: =H22*ASSUMPTIONS!$B$59 | I29: =I22*ASSUMPTIONS!$B$59 | ... M29: =M22*ASSUMPTIONS!$B$59 | N29: =SUM(B29:M29)
A30: Office & Ops | B30: 20000 | C30: 22000 | D30: 25000 | E30: 30000 | F30: 30000 | G30: 32000 | H30: 35000 | I30: 38000 | J30: 42000 | K30: 50000 | L30: 50000 | M30: 50000 | N30: =SUM(B30:M30)
A31: Legal | B31: 10000 | C31: 12000 | D31: 15000 | E31: 25000 | F31: 25000 | G31: 28000 | H31: 32000 | I31: 36000 | J31: 40000 | K31: 50000 | L31: 50000 | M31: 50000 | N31: =SUM(B31:M31)
A32: Misc/Contingency (5%) | B32: =(B26+B28+B27)*0.05 | C32: =(C26+C28+C27)*0.05 | D32: =(D26+D28+D27)*0.05 | E32: =(E26+E28+E27)*0.05 | F32: =(F26+F28+F27)*0.05 | G32: =(G26+G28+G27)*0.05 | H32: =(H26+H28+H27)*0.05 | I32: =(I26+I28+I27)*0.05 | ... M32: =(M26+M28+M27)*0.05 | N32: =SUM(B32:M32)
A33: TOTAL OPEX | B33: =B26+B27+B28+B29+B30+B31+B32 | C33: =C26+C27+C28+C29+C30+C31+C32 | D33: =D26+D27+D28+D29+D30+D31+D32 | E33: =E26+E27+E28+E29+E30+E31+E32 | F33: =F26+F27+F28+F29+F30+F31+F32 | G33: =G26+G27+G28+G29+G30+G31+G32 | H33: =H26+H27+H28+H29+H30+H31+H32 | I33: =I26+I27+I28+I29+I30+I31+I32 | ... M33: =M26+M27+M28+M29+M30+M31+M32 | N33: =SUM(B33:M33)
A34: GROSS PROFIT & MARGINS
A35: COGS (Compute + Payment Proc) | B35: =B27+B29 | C35: =C27+C29 | D35: =D27+D29 | E35: =E27+E29 | F35: =F27+F29 | G35: =G27+G29 | H35: =H27+H29 | I35: =I27+I29 | ... M35: =M27+M29 | N35: =SUM(B35:M35)
A36: Gross Profit | B36: =B22-B35 | C36: =C22-C35 | D36: =D22-D35 | E36: =E22-E35 | F36: =F22-F35 | G36: =G22-G35 | H36: =H22-H35 | I36: =I22-I35 | ... M36: =M22-M35 | N36: =SUM(B36:M36)
A37: Gross Margin % | B37: =IFERROR(B36/B22,0) | C37: =IFERROR(C36/C22,0) | D37: =IFERROR(D36/D22,0) | E37: =IFERROR(E36/E22,0) | F37: =IFERROR(F36/F22,0) | G37: =IFERROR(G36/G22,0) | H37: =IFERROR(H36/H22,0) | I37: =IFERROR(I36/I22,0) | ... N37: =IFERROR(N36/N22,0)
A38: EBITDA | B38: =B36-(B26+B28+B30+B31+B32) | C38: =C36-(C26+C28+C30+C31+C32) | D38: =D36-(D26+D28+D30+D31+D32) | E38: =E36-(E26+E28+E30+E31+E32) | F38: =F36-(F26+F28+F30+F31+F32) | G38: =G36-(G26+G28+G30+G31+G32) | H38: =H36-(H26+H28+H30+H31+H32) | I38: =I36-(I26+I28+I30+I31+I32) | ... M38: =M36-(M26+M28+M30+M31+M32) | N38: =SUM(B38:M38)
A39: EBITDA Margin % | B39: =IFERROR(B38/B22,0) | C39: =IFERROR(C38/C22,0) | D39: =IFERROR(D38/D22,0) | E39: =IFERROR(E38/E22,0) | F39: =IFERROR(F38/F22,0) | G39: =IFERROR(G38/G22,0) | H39: =IFERROR(H38/H22,0) | I39: =IFERROR(I38/I22,0) | ... N39: =IFERROR(N38/N22,0)

Sheet YEARS 2-5 QUARTERLY
A1: PUREBRAIN.AI — YEARS 2–5 QUARTERLY MODEL (2027–2030)
A2: Base case shown. Use ASSUMPTIONS!B5 to switch scenarios. Quarterly growth interpolated from annual targets.
A4: METRIC | B4: Q1 2027 | C4: Q2 2027 | D4: Q3 2027 | E4: Q4 2027 | F4: Q1 2028 | G4: Q2 2028 | H4: Q3 2028 | I4: Q4 2028 | J4: Q1 2029 | K4: Q2 2029 | L4: Q3 2029 | M4: Q4 2029 | N4: Q1 2030 | O4: Q2 2030 | P4: Q3 2030 | Q4: Q4 2030 | R4: 5-YR CUMUL
A5: QUARTERLY REVENUE
A6: Monthly MRR Run Rate | B6: 350000000 | C6: 400000000 | D6: 450000000 | E6: 500000000 | F6: 750000000 | G6: 1000000000 | H6: 1250000000 | I6: 1275000000 | J6: 2100000000 | K6: 2500000000 | L6: 3000000000 | M6: 3500000000 | N6: 4000000000 | O6: 4200000000 | P6: 4400000000 | Q6: 4600000000 | R6: =SUM(B6:Q6)
A7: Quarterly Revenue (MRR×3) | B7: 1050000000 | C7: 1200000000 | D7: 1350000000 | E7: 1500000000 | F7: 2250000000 | G7: 3000000000 | H7: 3750000000 | I7: 3825000000 | J7: 6300000000 | K7: 7500000000 | L7: 9000000000 | M7: 10500000000 | N7: 12000000000 | O7: 12600000000 | P7: 13200000000 | Q7: 13800000000 | R7: =SUM(B7:Q7)
A8: Active Subscribers (EOP) | B8: 600000 | C8: 700000 | D8: 850000 | E8: 1000000 | F8: 2000000 | G8: 3000000 | H8: 4000000 | I8: 5000000 | J8: 8000000 | K8: 10000000 | L8: 13000000 | M8: 17000000 | N8: 20000000 | O8: 22000000 | P8: 24000000 | Q8: 26000000 | R8: =SUM(B8:Q8)
A9: QoQ MRR Growth % | B9: =IFERROR((B5-186629459)/186629459,0) | C9: =IFERROR((C6-B6)/B6,0) | D9: =IFERROR((D6-C6)/C6,0) | E9: =IFERROR((E6-D6)/D6,0) | F9: =IFERROR((F6-E6)/E6,0) | G9: =IFERROR((G6-F6)/F6,0) | H9: =IFERROR((H6-G6)/G6,0) | I9: =IFERROR((I6-H6)/H6,0) | J9: =IFERROR((J6-I6)/I6,0) | ... Q9: =IFERROR((Q6-P6)/P6,0) | R9: =AVERAGE(C9:Q9)
A10: P&L SUMMARY
A11: Total Revenue | B11: 1050000000 | C11: 1200000000 | D11: 1350000000 | E11: 1500000000 | F11: 2250000000 | G11: 3000000000 | H11: 3750000000 | I11: 3825000000 | J11: 6300000000 | K11: 7500000000 | L11: 9000000000 | M11: 10500000000 | N11: 12000000000 | O11: 12600000000 | P11: 13200000000 | Q11: 13800000000 | R11: =SUM(B11:Q11)
A12: COGS | B12: 210000000 | C12: 2.28e+08 | D12: 243000000 | E12: 255000000 | F12: 382500000 | G12: 480000000 | H12: 600000000 | I12: 573750000 | J12: 945000000 | K12: 1125000000 | L12: 1260000000 | M12: 1470000000 | N12: 1680000000 | O12: 1638000000 | P12: 1716000000 | Q12: 1794000000 | R12: =SUM(B12:Q12)
A13: Gross Profit | B13: 840000000 | C13: 9.72e+08 | D13: 1107000000 | E13: 1245000000 | F13: 1867500000 | G13: 2520000000 | H13: 3150000000 | I13: 3251250000 | J13: 5355000000 | K13: 6375000000 | L13: 7740000000 | M13: 9030000000 | N13: 10320000000 | O13: 10962000000 | P13: 11484000000 | Q13: 12006000000 | R13: =SUM(B13:Q13)
A14: Gross Margin % | B14: 0.8 | C14: 0.81 | D14: 0.82 | E14: 0.83 | F14: 0.83 | G14: 0.84 | H14: 0.84 | I14: 0.85 | J14: 0.85 | K14: 0.85 | L14: 0.86 | M14: 0.86 | N14: 0.86 | O14: 0.87 | P14: 0.87 | Q14: 0.87 | R14: =AVERAGE(B14:Q14)
A15: Operating Expenses | B15: 210000000 | C15: 2.28e+08 | D15: 243000000 | E15: 255000000 | F15: 360000000 | G15: 4.8e+08 | H15: 562500000 | I15: 573750000 | J15: 945000000 | K15: 1050000000 | L15: 1350000000 | M15: 1470000000 | N15: 1680000000 | O15: 1890000000 | P15: 1848000000 | Q15: 1932000000 | R15: =SUM(B15:Q15)
A16: EBITDA | B16: 630000000 | C16: 744000000 | D16: 864000000 | E16: 990000000 | F16: 1507500000 | G16: 2040000000 | H16: 2587500000 | I16: 2677500000 | J16: 4410000000 | K16: 5325000000 | L16: 6390000000 | M16: 7560000000 | N16: 8640000000 | O16: 9072000000 | P16: 9636000000 | Q16: 10074000000 | R16: =SUM(B16:Q16)
A17: EBITDA Margin % | B17: 0.6 | C17: 0.62 | D17: 0.64 | E17: 0.66 | F17: 0.67 | G17: 0.68 | H17: 0.69 | I17: 0.7 | J17: 0.7 | K17: 0.71 | L17: 0.71 | M17: 0.72 | N17: 0.72 | O17: 0.72 | P17: 0.73 | Q17: 0.73 | R17: =AVERAGE(B17:Q17)
A18: KEY SAAS METRICS
A19: Blended ARPU/Month | B19: 583.33333 | C19: 571.42857 | D19: 529.41176 | E19: 500 | F19: 375 | G19: 333.33333 | H19: 312.5 | I19: 255 | J19: 262.5 | K19: 250 | L19: 230.76923 | M19: 205.88235 | N19: 200 | O19: 190.90909 | P19: 183.33333 | Q19: 176.92308 | R19: =AVERAGE(B19:Q19)
A20: CAC | B20: 45 | C20: 40 | D20: 35 | E20: 30 | F20: 28 | G20: 25 | H20: 23 | I20: 22 | J20: 21 | K20: 20 | L20: 20 | M20: 20 | N20: 20 | O20: 20 | P20: 20 | Q20: 20 | R20: =AVERAGE(B20:Q20)
A21: LTV (blended) | B21: 16666.667 | C21: 16326.531 | D21: 15126.05 | E21: 14285.714 | F21: 10714.286 | G21: 9523.8095 | H21: 8928.5714 | I21: 7285.7143 | J21: 7500 | K21: 7142.8571 | L21: 6593.4066 | M21: 5882.3529 | N21: 5714.2857 | O21: 5454.5455 | P21: 5238.0952 | Q21: 5054.9451 | R21: =AVERAGE(B21:Q21)
A22: LTV:CAC Ratio | B22: 370.37037 | C22: 408.16327 | D22: 432.17287 | E22: 476.19048 | F22: 382.65306 | G22: 380.95238 | H22: 388.19876 | I22: 331.16883 | J22: 357.14286 | K22: 357.14286 | L22: 329.67033 | M22: 294.11765 | N22: 285.71429 | O22: 272.72727 | P22: 261.90476 | Q22: 252.74725 | R22: =AVERAGE(B22:Q22)
A23: Net Revenue Retention | B23: 1.12 | C23: 1.13 | D23: 1.14 | E23: 1.15 | F23: 1.16 | G23: 1.17 | H23: 1.18 | I23: 1.19 | J23: 1.2 | K23: 1.21 | L23: 1.22 | M23: 1.23 | N23: 1.24 | O23: 1.24 | P23: 1.25 | Q23: 1.25 | R23: =AVERAGE(B23:Q23)

Sheet P&L STATEMENT
A1: PUREBRAIN.AI — INCOME STATEMENT | GAAP-FORMAT
A3: LINE ITEM | B3: Mar-26 | C3: Apr-26 | D3: May-26 | E3: Jun-26 | F3: Jul-26 | G3: Aug-26 | H3: Sep-26 | I3: Oct-26 | J3: Nov-26 | K3: Dec-26 | L3: Jan-27 | M3: Feb-27 | N3: FY 2026
A4: REVENUE
A5: Consumer Subscription Revenue | B5: 33786 | C5: 360614 | D5: 3443897 | E5: 33950594 | F5: 43049286 | G5: 53545226 | H5: 66092957 | I5: 80647850 | J5: 97721594 | K5: 117779512 | L5: 141394074 | M5: 169129459 | N5: 807148849
A6: Enterprise License Revenue | B6: 20000 | C6: 50000 | D6: 300000 | E6: 2250000 | F6: 3000000 | G6: 3750000 | H6: 5000000 | I6: 6500000 | J6: 8500000 | K6: 11000000 | L6: 14000000 | M6: 17500000 | N6: 71870000
A7: TOTAL NET REVENUE | B7: 53786 | C7: 410614 | D7: 3743897 | E7: 36200594 | F7: 46049286 | G7: 57295226 | H7: 71092957 | I7: 87147850 | J7: 106221594 | K7: 128779512 | L7: 155394074 | M7: 186629459 | N7: 879018849
A8: COST OF REVENUE (COGS)
A9: AI / Cloud Compute | B9: 2500 | C9: 18900 | D9: 119856 | E9: 689220 | F9: 875000 | G9: 1088000 | H9: 1341000 | I9: 1637000 | J9: 1983000 | K9: 2391000 | L9: 2870000 | M9: 3432000 | N9: 16447476
A10: Payment Processing (3%) | B10: 1613 | C10: 12318 | D10: 112316 | E10: 1086017 | F10: 1381478 | G10: 1718856 | H10: 2132788 | I10: 2614435 | J10: 3186647 | K10: 3863385 | L10: 4661822 | M10: 5598883 | N10: 26370558
A11: TOTAL COGS | B11: 4113 | C11: 31218 | D11: 232172 | E11: 1775237 | F11: 2256478 | G11: 2806856 | H11: 3473788 | I11: 4251435 | J11: 5169647 | K11: 6254385 | L11: 7531822 | M11: 9030883 | N11: 42818034
A12: GROSS PROFIT | B12: 49673 | C12: 379396 | D12: 3511725 | E12: 34425357 | F12: 43792808 | G12: 54488370 | H12: 67619169 | I12: 82896415 | J12: 101051947 | K12: 122525127 | L12: 147862252 | M12: 177598576 | N12: 836200815
A13: Gross Margin % | B13: 0.92353029 | C13: 0.92397239 | D13: 0.93798654 | E13: 0.95096111 | F13: 0.95099863 | G13: 0.95101065 | H13: 0.95113738 | I13: 0.95121584 | J13: 0.95133149 | K13: 0.95143338 | L13: 0.95153083 | M13: 0.95161062 | N13: 11.346719
A14: OPERATING EXPENSES
A15: Payroll & Benefits | B15: 480000 | C15: 550000 | D15: 650000 | E15: 800000 | F15: 800000 | G15: 850000 | H15: 900000 | I15: 920000 | J15: 950000 | K15: 980000 | L15: 1000000 | M15: 1000000 | N15: 9880000
A16: Sales & Marketing | B16: 5000 | C16: 56000 | D16: 517000 | E16: 4988000 | F16: 6355000 | G16: 7905000 | H16: 9806000 | I16: 12027000 | J16: 14674000 | K16: 20069000 | L16: 21470000 | M16: 25746000 | N16: 123618000
A17: Office & Operations | B17: 20000 | C17: 22000 | D17: 25000 | E17: 30000 | F17: 30000 | G17: 32000 | H17: 35000 | I17: 38000 | J17: 42000 | K17: 50000 | L17: 50000 | M17: 50000 | N17: 424000
A18: Legal & Compliance | B18: 10000 | C18: 12000 | D18: 15000 | E18: 25000 | F18: 25000 | G18: 28000 | H18: 32000 | I18: 36000 | J18: 40000 | K18: 50000 | L18: 50000 | M18: 50000 | N18: 373000
A19: Misc & Contingency (5%) | B19: 24375 | C19: 31245 | D19: 64342 | E19: 323861 | F19: 401500 | G19: 492150 | H19: 602350 | I19: 729200 | J19: 880350 | K19: 1172000 | L19: 1267000 | M19: 1508900 | N19: 7497273
A20: TOTAL OPERATING EXPENSES | B20: 539375 | C20: 671245 | D20: 1271342 | E20: 6166861 | F20: 7611500 | G20: 9307150 | H20: 11375350 | I20: 13750200 | J20: 16586350 | K20: 22321000 | L20: 23837000 | M20: 28354900 | N20: 141792273
A21: PROFITABILITY
A22: EBITDA | B22: -489702 | C22: -291849 | D22: 2240383 | E22: 28258496 | F22: 36181308 | G22: 45181220 | H22: 56243819 | I22: 69146215 | J22: 84465597 | K22: 100204127 | L22: 124025252 | M22: 149243676 | N22: 694408542
A23: EBITDA Margin % | B23: -9.1046369 | C23: -0.71076242 | D23: 0.59840936 | E23: 0.78060863 | F23: 0.78570834 | G23: 0.78856867 | H23: 0.79113067 | I23: 0.7934357 | J23: 0.79518292 | K23: 0.77810612 | L23: 0.79813373 | M23: 0.79967909 | N23: -2.1064361
A24: Net Revenue (ARR) | B24: 645432 | C24: 4927368 | D24: 44926764 | E24: 434407128 | F24: 552591432 | G24: 687542712 | H24: 853115484 | I24: 1045774200 | J24: 1274659128 | K24: 1545354144 | L24: 1864728888 | M24: 2239553508 | N24: 10548226188
A27: ANNUAL SUMMARY (all years)
A28: Year | B28: Revenue | C28: Gross Profit | D28: EBITDA | E28: EBITDA Margin | F28: Subscribers (EOP)
A29: Year 1 (2026) | B29: 733000000 | C29: 545000000 | D29: 300000000 | E29: 0.41 | F29: 490000
A30: Year 2 (2027) | B30: 5400000000 | C30: 4320000000 | D30: 3240000000 | E30: 0.6 | F30: 1000000
A31: Year 3 (2028) | B31: 15300000000 | C31: 12900000000 | D31: 10710000000 | E31: 0.7 | F31: 5000000
A32: Year 4 (2029) | B32: 33500000000 | C32: 28775000000 | D32: 24120000000 | E32: 0.72 | F32: 17000000
A33: Year 5 (2030) | B33: 50700000000 | C33: 44109000000 | D33: 37011000000 | E33: 0.73 | F33: 26000000

Sheet UNIT ECONOMICS
A1: PUREBRAIN.AI — UNIT ECONOMICS & SAAS METRICS
A3: METRIC | B3: Mar 2026 | C3: Jun 2026 | D3: Dec 2026 | E3: Year 2 | F3: Year 3 | G3: Year 4 | H3: Year 5
A4: ARPU & PRICING
A5: Awakened ARPU/Mo | B5: 197 | C5: 197 | D5: 197 | E5: 197 | F5: 197 | G5: 197 | H5: 197
A6: Partnered ARPU/Mo | B6: 579 | C6: 579 | D6: 579 | E6: 579 | F6: 579 | G6: 579 | H6: 579
A7: Unified ARPU/Mo | B7: 1089 | C7: 1089 | D7: 1089 | E7: 1089 | F7: 1089 | G7: 1089 | H7: 1089
A8: Blended Consumer ARPU | B8: 344.76 | C8: 344.76 | D8: 344.76 | E8: 344.76 | F8: 344.76 | G8: 344.76 | H8: 344.76
A9: Enterprise ARPU/Mo | B9: 10000 | C9: 15000 | D9: 15019 | E9: 18000 | F9: 20000 | G9: 20000 | H9: 20000
A10: CUSTOMER ACQUISITION
A11: CAC ($) | B11: 150 | C11: 90 | D11: 45 | E11: 30 | F11: 20 | G11: 20 | H11: 20
A12: Payback Period (months) | B12: 2.2 | C12: 1.1 | D12: 0.5 | E12: 0.3 | F12: 0.2 | G12: 0.2 | H12: 0.2
A13: Viral / Organic % | B13: 0.15 | C13: 0.25 | D13: 0.4 | E13: 0.55 | F13: 0.65 | G13: 0.7 | H13: 0.75
A14: LIFETIME VALUE BY TIER
A15: Awakened LTV | B15: 4334 | C15: 4334 | D15: 4334 | E15: 4334 | F15: 4334 | G15: 4334 | H15: 4334
A16: Partnered LTV | B16: 19107 | C16: 19107 | D16: 19107 | E16: 19107 | F16: 19107 | G16: 19107 | H16: 19107
A17: Unified LTV | B17: 54450 | C17: 54450 | D17: 54450 | E17: 54450 | F17: 54450 | G17: 54450 | H17: 54450
A18: Enterprise LTV | B18: 670000 | C18: 670000 | D18: 670000 | E18: 670000 | F18: 670000 | G18: 670000 | H18: 670000
A19: Blended LTV (consumer) | B19: 4800 | C19: 6200 | D19: 8500 | E19: 12000 | F19: 18000 | G19: 22000 | H19: 25000
A20: LTV : CAC & EFFICIENCY
A21: LTV:CAC Ratio | B21: 28 | C21: 46 | D21: 92 | E21: 225 | F21: 400 | G21: 500 | H21: 550
A22: NRR (Net Revenue Retention) | B22: 1.07 | C22: 1.12 | D22: 1.18 | E22: 1.22 | F22: 1.25 | G22: 1.25 | H22: 1.25
A23: CHURN ANALYSIS
A24: Awakened Monthly Churn | B24: 0.045 | C24: 0.045 | D24: 0.045 | E24: 0.045 | F24: 0.045 | G24: 0.045 | H24: 0.045
A25: Partnered Monthly Churn | B25: 0.03 | C25: 0.03 | D25: 0.03 | E25: 0.03 | F25: 0.03 | G25: 0.03 | H25: 0.03
A26: Unified Monthly Churn | B26: 0.02 | C26: 0.02 | D26: 0.02 | E26: 0.02 | F26: 0.02 | G26: 0.02 | H26: 0.02
A27: Enterprise Monthly Churn | B27: 0.015 | C27: 0.015 | D27: 0.015 | E27: 0.015 | F27: 0.015 | G27: 0.015 | H27: 0.015
A28: Blended Consumer Churn | B28: 0.042 | C28: 0.038 | D28: 0.035 | E28: 0.032 | F28: 0.03 | G28: 0.03 | H28: 0.03
A29: Annual Churn Rate | B29: 0.504 | C29: 0.456 | D29: 0.42 | E29: 0.384 | F29: 0.36 | G29: 0.36 | H29: 0.36
A30: Avg Customer Life (months) | B30: 22 | C30: 26 | D30: 29 | E30: 31 | F30: 33 | G30: 33 | H30: 33
A31: MARGIN PROFILE
A32: Gross Margin | B32: 0.68 | C32: 0.74 | D32: 0.79 | E32: 0.83 | F32: 0.85 | G32: 0.86 | H32: 0.87
A33: EBITDA Margin | B33: 0.12 | C33: 0.41 | D33: 0.56 | E33: 0.6 | F33: 0.7 | G33: 0.72 | H33: 0.73
A34: CAC Payback Ratio | B34: 0.44 | C34: 0.26 | D34: 0.13 | E34: 0.09 | F34: 0.06 | G34: 0.06 | H34: 0.06
A35: MILESTONE TRACKER
A36: $1M MRR | B36: Mar 2026 ✓
A37: $10M MRR | B37: Apr 2026 ✓
A38: $100M MRR | C38: May 2026 ✓
A39: $1B MRR | D39: Q2 2028 ✓
A40: $10B ARR | E40: Q3 2028 ✓
A41: $100B ARR | F41: Q1 2030 ✓

Sheet INVESTOR DASHBOARD
A1: PUREBRAIN.AI — INVESTOR DASHBOARD | 5-YEAR FINANCIAL SUMMARY
A2: Prepared: March 16, 2026 | All figures USD | Base Case (change scenario in ASSUMPTIONS!B5)
A4: KEY PERFORMANCE INDICATORS — CURRENT STATE & PROJECTIONS
A5: Launch MRR (Mar 2026) | B5: $53,786 | D5: Year 1 MRR (Feb 2027) | E5: $186.6M | G5: Year 2 ARR | H5: Year 2 ARR | I5: $5.4B
A6: Year 1 Cumulative Revenue | B6: $733M | D6: Year 3 ARR | E6: $15.3B | G6: Year 5 ARR | H6: Year 5 ARR | I6: $50.7B
A7: 5-Year Cumulative Revenue | B7: $105.6B | D7: Peak Gross Margin | E7: 87% | G7: Peak EBITDA Margin | H7: Peak EBITDA Margin | I7: 73%
A8: Launch LTV:CAC | B8: 28:1 | D8: Mature LTV:CAC | E8: 225:1 | G8: NRR at Scale | H8: NRR at Scale | I8: 125%
A9: $1B MRR Milestone | B9: Q2 2028 | D9: Time to $1B ARR | E9: ~9 months | G9: Users at $1B ARR | H9: Users at $1B ARR | I9: ~2.9M
A11: MRR TRAJECTORY & ANNUAL COMPARISON
A12: Period | B12: MRR | C12: ARR | D12: Subscribers | E12: Consumer MRR | F12: Enterprise MRR | G12: Gross Margin | H12: EBITDA Margin | I12: LTV:CAC | J12: NRR
A13: Mar 2026 | B13: 53786 | C13: 645432 | D13: 98 | E13: 33786 | F13: 20000 | G13: 0.68 | H13: 0.12 | I13: 28 | J13: 1.07
A14: Jun 2026 | B14: 36200594 | C14: 434407128 | D14: 98460 | E14: 33950594 | F14: 2250000 | G14: 0.74 | H14: 0.41 | I14: 46 | J14: 1.12
A15: Dec 2026 | B15: 128779512 | C15: 1545354144 | D15: 341620 | E15: 117779512 | F15: 11000000 | G15: 0.79 | H15: 0.56 | I15: 92 | J15: 1.18
A16: Feb 2027 | B16: 186629459 | C16: 2239553508 | D16: 490561 | E16: 169129459 | F16: 17500000 | G16: 0.8 | H16: 0.6 | I16: 110 | J16: 1.19
A17: Year 2 | B17: 450000000 | C17: 5400000000 | D17: 1000000 | E17: 390000000 | F17: 60000000 | G17: 0.83 | H17: 0.6 | I17: 225 | J17: 1.22
A18: Year 3 | B18: 1275000000 | C18: 15300000000 | D18: 5000000 | E18: 1125000000 | F18: 150000000 | G18: 0.85 | H18: 0.7 | I18: 400 | J18: 1.25
A19: Year 4 | B19: 2791666667 | C19: 33500000000 | D19: 17000000 | E19: 2641666667 | F19: 150000000 | G19: 0.86 | H19: 0.72 | I19: 500 | J19: 1.25
A20: Year 5 | B20: 4225000000 | C20: 50700000000 | D20: 26000000 | E20: 4075000000 | F20: 150000000 | G20: 0.87 | H20: 0.73 | I20: 550 | J20: 1.25
A22: BULL / BASE / BEAR SCENARIO COMPARISON
A23: Metric | B23: Bear Case | C23: Base Case | D23: Bull Case | E23: Bear vs Base | F23: Bull vs Base
A24: Dec 2026 MRR | B24: $48M | C24: $128M | D24: $285M | E24: -63% | F24: +123%
A25: Year 1 Revenue | B25: $267M | C25: $733M | D25: $1.6B | E25: -64% | F25: +118%
A26: $1B MRR Milestone | B26: Q4 2029 | C26: Q2 2028 | D26: Q4 2027 | E26: +6 qtrs | F26: -2 qtrs
A27: Year 3 ARR | B27: $8.1B | C27: $15.3B | D27: $28.0B | E27: -47% | F27: +83%
A28: Year 5 ARR | B28: $22B | C28: $50.7B | D28: $85B | E28: -57% | F28: +68%
A29: Peak Subscribers | B29: 10M | C29: 26M | D29: 45M | E29: -62% | F29: +73%
A30: Peak EBITDA Margin | B30: 68% | C30: 73% | D30: 76% | E30: -5 pts | F30: +3 pts
A32: "WHAT HAS TO BE TRUE" — KEY ASSUMPTIONS CHECKLIST
A33: Assumption | B33: Confidence | C33: Why / Mechanism
A34: Base Case: Viral K-factor ≥ 0.25 by Month 3 | B34: HIGH | C34: Product quality + referral incentives
A35: Base Case: Churn stays ≤ 4.2% Month 1 | B35: HIGH | C35: Onboarding quality + time-to-value < 48h
A36: Base Case: Enterprise pipeline closes 25+ by M3 | B36: MEDIUM | C36: Direct outreach + PLG conversion
A37: Base Case: CAC drops from $150 → $45 by Month 10 | B37: HIGH | C37: Organic growth kicking in at scale
A38: Base Case: Gross margin reaches 79% by Dec 2026 | B38: MEDIUM | C38: Compute economies of scale realized
A39: Bull Case: Month 4 +90K sign-ups (viral moment) | B39: SPECULATIVE | C39: Product goes viral / influencer catalyst
A40: Bear Case: Only 67 sign-ups in Month 1 | B40: LOW | C40: Risk: slow initial traction
A41: All Cases: Hard cap of 100 FTEs holds | B41: HIGH | C41: AI-leverage model — no large team needed
A43: CASH FLOW SUMMARY & RUNWAY
A44: Month | B44: Opening Cash | C44: Revenue | D44: OPEX | E44: Net Cash Flow | F44: Closing Cash | G44: Runway (mo) | H44: Cumul Revenue
A45: Mar-26 | B45: 5000000 | C45: 53786 | D45: 592000 | E45: -538214 | F45: 4461786 | G45: 7.5 | H45: 53786
...

Sheet SCENARIO ENGINE
A1: PUREBRAIN.AI — SCENARIO ENGINE & SENSITIVITY ANALYSIS
A3: THREE-SCENARIO SIDE-BY-SIDE
A4: Variable | B4: Bear Case | C4: Base Case | D4: Bull Case | E4: Bear Delta | F4: Bull Delta
A5: KEY ASSUMPTIONS
A6: Growth Multiplier | B6: 0.67 | C6: 1 | D6: 1.4 | E6: -0.33 | F6: 0.4
A7: Month 1 Sign-Ups | B7: 67 | C7: 100 | D7: 140 | E7: -0.33 | F7: 0.4
A8: Month 4 Sign-Ups | B8: 60000 | C8: 90000 | D8: 126000 | E8: -0.33333333 | F8: 0.4
A9: Month 12 Sign-Ups | B9: 67000 | C9: 100000 | D9: 140000 | E9: -0.33 | F9: 0.4
A10: Blended Churn (M1) | B10: 0.055 | C10: 0.042 | D10: 0.03 | E10: 0.30952381 | F10: -0.28571429
A11: Viral K-Factor | B11: 0.1 | C11: 0.25 | D11: 0.45 | E11: -0.6 | F11: 0.8
A12: CAC (M1) | B12: 200 | C12: 150 | D12: 100 | E12: 0.33333333 | F12: -0.33333333
A13: Enterprise Conv Rate | B13: 0.01 | C13: 0.018 | D13: 0.03 | E13: -0.44444444 | F13: 0.66666667
A14: YEAR 1 OUTCOMES
A15: Dec 2026 MRR | B15: 48000000 | C15: 128779512 | D15: 285000000 | E15: -0.6272699 | F15: 1.213085
A16: Year 1 Revenue | B16: 267000000 | C16: 733000000 | D16: 1600000000 | E16: -0.63574352 | F16: 1.1828104
A17: Year 1 Subscribers | B17: 160000 | C17: 490561 | D17: 1100000 | E17: -0.6738428 | F17: 1.2423307
A18: Year 1 EBITDA | B18: 60000000 | C18: 300000000 | D18: 700000000 | E18: -0.8 | F18: 1.3333333
A19: Year 1 Gross Margin | B19: 0.72 | C19: 0.79 | D19: 0.83 | E19: -0.088607595 | F19: 0.050632911
A20: 5-YEAR OUTCOMES
A21: Year 3 ARR | B21: 8100000000 | C21: 15300000000 | D21: 28000000000 | E21: -0.47058824 | F21: 0.83006536
A22: Year 5 ARR | B22: 22000000000 | C22: 50700000000 | D22: 85000000000 | E22: -0.56607495 | F22: 0.6765286
A23: $1B MRR Milestone | B23: Q4 2029 | C23: Q2 2028 | D23: Q4 2027 | E23: 0 | F23: 0
A24: Peak Subscribers | B24: 10000000 | C24: 26000000 | D24: 45000000 | E24: -0.61538462 | F24: 0.73076923
A25: 5-Year Cumulative Rev | B25: 38500000000 | C25: 105600000000 | D25: 200000000000 | E25: -0.63541667 | F25: 0.89393939
A28: SENSITIVITY TABLE — Dec 2026 MRR vs CHURN & GROWTH
A29: Growth Mult ↓ | B29: 2.0% | C29: 3.0% | D29: 3.5% | E29: 4.0% | F29: 5.0% | G29: 6.0%
A30: 0.50x growth | B30: 65390633 | C30: 64723382 | D30: 64389756 | E30: 64056130 | F30: 63388879 | G30: 62721628
A31: 0.67x growth | B31: 87623448 | C31: 86729331 | D31: 86282273 | E31: 85835215 | F31: 84941098 | G31: 84046981
A32: 1.00x growth | B32: 130781266 | C32: 129446763 | D32: 128779512 | E32: 128112261 | F32: 126777758 | G32: 125443255
A33: 1.20x growth | B33: 156937519 | C33: 155336116 | D33: 154535414 | E33: 153734713 | F33: 152133310 | G33: 150531906
A34: 1.40x growth | B34: 183093773 | C34: 181225469 | D34: 180291317 | E34: 179357165 | F34: 177488861 | G34: 175620557
A35: 1.60x growth | B35: 209250026 | C35: 207114821 | D35: 206047219 | E35: 204979617 | F35: 202844413 | G35: 200709208
A38: TORNADO ANALYSIS — KEY DRIVER IMPACT ON Year 1 Revenue
A39: Variable | B39: -1 SD Impact | C39: Base Case | D39: +1 SD Impact | E39: Range
A40: Month 4 Growth (±50%) | B40: 390000000 | C40: 733000000 | D40: 1100000000 | E40: 710000000
A41: Blended Churn (±1.5%) | B41: 550000000 | C41: 733000000 | D41: 920000000 | E41: 370000000
A42: ARPU (±$50) | B42: 610000000 | C42: 733000000 | D42: 856000000 | E42: 246000000
A43: CAC (±$50) | B43: 650000000 | C43: 733000000 | D43: 816000000 | E43: 166000000
A44: Enterprise Uptake (±50%) | B44: 680000000 | C44: 733000000 | D44: 786000000 | E44: 106000000
A45: Gross Margin (±5%) | B45: 686000000 | C45: 733000000 | D45: 780000000 | E45: 94000000
